Workbook

Sheet Estimator
A1: EDC Plastic Cost Estimator
A2: Enter fuse and relay counts. Get housing + cover size, weight and per-part cost.
A3: Legend: yellow cells with blue text are inputs; everything else is calculated. Material and molding assumptions live on the Assumptions tab.
A5: Inputs | D5: Results
A6: Fuses | B6: Count | D6: Plastic cost per EDC set | E6: =Calc!B58 -> 1.6597622
A7: Micro2 | B7: 20 | D7: Total plastic (g) | E7: =Calc!B59 -> 306.19814
A8: Micro3 | B8: 10 | D8: Outer footprint L (mm) | E8: =Calc!B27 -> 166.19538
A9: M-Case | B9: 6 | D9: Outer footprint W (mm) | E9: =Calc!B28 -> 118.13025
A10: A1S (placeholder size) | B10: 2 | D10: Stack height (mm) | E10: =Calc!B60 -> 70
A11: PCB relays | B11: Count
A12: Micro PCB relay (up to 35 A) | B12: 8 | D12: Marginal cost
A13: Mini PCB relay (35-70 A) | B13: 4 | D13: Each extra Micro2 adds | E13: =Calc!C58-Calc!B58 -> 0.0079744791
A14: High-current PCB relay (70 A+) | B14: 0 | D14: Each extra Micro3 adds | E14: =Calc!D58-Calc!B58 -> 0.01212426
A15: Options | B15: Value | D15: Each extra Micro PCB relay adds | E15: =Calc!E58-Calc!B58 -> 0.019769084
A16: Relay layout (relative to fuses) | B16: Beside
A17: Cavities per mold | B17: 2
A18: Main housing resin | B18: PA66-GF30
A19: Upper cover resin | B19: PA66-GF30
A20: Lower cover resin | B20: PA66-GF30
A22: Per-part breakdown
B23: Main housing | C23: Upper cover | D23: Lower cover
A24: Resin | B24: =Estimator!$B$18 -> PA66-GF30 | C24: =Estimator!$B$19 -> PA66-GF30 | D24: =Estimator!$B$20 -> PA66-GF30
A25: L (mm) | B25: =Calc!B23 -> 161.19538 | C25: =Calc!B27 -> 166.19538 | D25: =Calc!B27 -> 166.19538
A26: W (mm) | B26: =Calc!B24 -> 113.13025 | C26: =Calc!B28 -> 118.13025 | D26: =Calc!B28 -> 118.13025
A27: H (mm) | B27: =Calc!B25 -> 28 | C27: =Calc!B29 -> 14 | D27: =Calc!B30 -> 28
A28: Volume (cm³) | B28: =Calc!B26/1000 -> 98.848174 | C28: =Calc!B31/1000 -> 55.18764 | D28: =Calc!B32/1000 -> 71.109876
A29: Mass (g) | B29: =Calc!B34 -> 134.43352 | C29: =Calc!B42 -> 75.055191 | D29: =Calc!B50 -> 96.709431
A30: Material | B30: =Calc!B35 -> 0.55171515 | C30: =Calc!B43 -> 0.3080265 | D30: =Calc!B51 -> 0.39689551
A31: Press tonnage (t) | B31: =Calc!B36 -> 197.8618 | C31: =Calc!B44 -> 213.01525 | D31: =Calc!B52 -> 213.01525
A32: Cycle time (s) | B32: =Calc!B37 -> 24.5 | C32: =Calc!B45 -> 20 | D32: =Calc!B53 -> 20
A33: Molding | B33: =Calc!B39 -> 0.153125 | C33: =Calc!B47 -> 0.125 | D33: =Calc!B55 -> 0.125
A34: Part cost | B34: =Calc!B40 -> 0.70484015 | C34: =Calc!B48 -> 0.4330265 | D34: =Calc!B56 -> 0.52189551
A36: Not ported from the web page: the to-scale plan view and its cavity-fit warning.

Sheet Assumptions
A1: Assumptions (edit the yellow cells to match your parts)
A2: Values are the defaults from the web estimator. Blue text on yellow = input. A1S footprint is a placeholder until real numbers are available.
A4: Component footprints
A5: Part | B5: L (mm) | C5: W (mm) | D5: H (mm)
A6: Micro2 | B6: 11.5 | C6: 6 | D6: 16
A7: Micro3 | B7: 17 | C7: 6.5 | D7: 15
A8: M-Case | B8: 15 | C8: 10 | D8: 14
A9: A1S (placeholder size) | B9: 20 | C9: 12 | D9: 18
A10: Micro PCB relay (up to 35 A) | B10: 16 | C10: 14 | D10: 15
A11: Mini PCB relay (35-70 A) | B11: 24 | C11: 18 | D11: 22
A12: High-current PCB relay (70 A+) | B12: 32 | C12: 24 | D12: 28
A14: Housing geometry
A15: Packing efficiency (0-1) | B15: 0.65
A16: Connector / stud area (mm²) | B16: 2500
A17: Edge margin (mm) | B17: 6
A18: Aspect ratio L:W | B18: 1.5
A19: Housing wall (mm) | B19: 2.5
A20: Cavity rib (mm) | B20: 1.2
A21: PCB + busbar stack (mm) | B21: 10
A22: Cover wall (mm) | B22: 2
A23: Fuse head above housing (mm) | B23: 8
A24: Cover clearance (mm) | B24: 6
A25: Min lower cover height (mm) | B25: 15
A27: Resins
A28: Resin | B28: Density (g/cm³) | C28: Price ($/kg)
A29: PA66-GF30 | B29: 1.36 | C29: 3.8
A30: PBT-GF30 | B30: 1.53 | C30: 3.2
A31: PP-T20 | B31: 1.05 | C31: 1.8
A33: Molding
A34: Runner / scrap (%) | B34: 0.08
A35: Cycle base (s) | B35: 12
A36: Cooling k (s/mm²) | B36: 2
A37: Clamp (tons/in²) | B37: 3.5
A38: Press rate <300 t ($/hr) | B38: 45
A39: Press rate 300-500 t ($/hr) | B39: 60
A40: Press rate 500-800 t ($/hr) | B40: 80
A41: Press rate >800 t ($/hr) | B41: 110
A43: Cycle time = base + k × wall².
A44: Clamp tonnage = projected area (in²) × tons/in² × cavities; press rate is picked from the tonnage bands.
A45: Molding cost per part = rate × cycle ÷ cavities. Material = mass × (1 + scrap) × $/kg.

Sheet Calc
A1: Calculation engine (no inputs here)
A2: Column B is the estimate. C-E add one part each so the Estimator can show marginal cost.
A3: Line item | B3: Base | C3: +1 Micro2 | D3: +1 Micro3 | E3: +1 Micro PCB relay
A4: Counts
A5: Micro2 count | B5: =Estimator!$B$7+0 -> 20 | C5: =Estimator!$B$7+1 -> 21 | D5: =Estimator!$B$7+0 -> 20 | E5: =Estimator!$B$7+0 -> 20
A6: Micro3 count | B6: =Estimator!$B$8+0 -> 10 | C6: =Estimator!$B$8+0 -> 10 | D6: =Estimator!$B$8+1 -> 11 | E6: =Estimator!$B$8+0 -> 10
A7: M-Case count | B7: =Estimator!$B$9+0 -> 6 | C7: =Estimator!$B$9+0 -> 6 | D7: =Estimator!$B$9+0 -> 6 | E7: =Estimator!$B$9+0 -> 6
A8: A1S (placeholder size) count | B8: =Estimator!$B$10+0 -> 2 | C8: =Estimator!$B$10+0 -> 2 | D8: =Estimator!$B$10+0 -> 2 | E8: =Estimator!$B$10+0 -> 2
A9: Micro PCB relay (up to 35 A) count | B9: =Estimator!$B$12+0 -> 8 | C9: =Estimator!$B$12+0 -> 8 | D9: =Estimator!$B$12+0 -> 8 | E9: =Estimator!$B$12+1 -> 9
A10: Mini PCB relay (35-70 A) count | B10: =Estimator!$B$13+0 -> 4 | C10: =Estimator!$B$13+0 -> 4 | D10: =Estimator!$B$13+0 -> 4 | E10: =Estimator!$B$13+0 -> 4
A11: High-current PCB relay (70 A+) count | B11: =Estimator!$B$14+0 -> 0 | C11: =Estimator!$B$14+0 -> 0 | D11: =Estimator!$B$14+0 -> 0 | E11: =Estimator!$B$14+0 -> 0
A12: Footprint
A13: Fuse cavity area (mm²) | B13: =B5*Assumptions!$B$6*Assumptions!$C$6+B6*Assumptions!$B$7*Assumptions!$C$7+B7*Assumptions!$B$8*Assumptions!$C$8+B8*Assumptions!$B$9*Assumptions!$C$9 -> 3865 | C13: =C5*Assumptions!$B$6*Assumptions!$C$6+C6*Assumptions!$B$7*Assumptions!$C$7+C7*Assumptions!$B$8*Assumptions!$C$8+C8*Assumptions!$B$9*Assumptions!$C$9 -> 3934 | D13: =D5*Assumptions!$B$6*Assumptions!$C$6+D6*Assumptions!$B$7*Assumptions!$C$7+D7*Assumptions!$B$8*Assumptions!$C$8+D8*Assumptions!$B$9*Assumptions!$C$9 -> 3975.5 | E13: =E5*Assumptions!$B$6*Assumptions!$C$6+E6*Assumptions!$B$7*Assumptions!$C$7+E7*Assumptions!$B$8*Assumptions!$C$8+E8*Assumptions!$B$9*Assumptions!$C$9 -> 3865
A14: Relay area (mm²) | B14: =B9*Assumptions!$B$10*Assumptions!$C$10+B10*Assumptions!$B$11*Assumptions!$C$11+B11*Assumptions!$B$12*Assumptions!$C$12 -> 3520 | C14: =C9*Assumptions!$B$10*Assumptions!$C$10+C10*Assumptions!$B$11*Assumptions!$C$11+C11*Assumptions!$B$12*Assumptions!$C$12 -> 3520 | D14: =D9*Assumptions!$B$10*Assumptions!$C$10+D10*Assumptions!$B$11*Assumptions!$C$11+D11*Assumptions!$B$12*Assumptions!$C$12 -> 3520 | E14: =E9*Assumptions!$B$10*Assumptions!$C$10+E10*Assumptions!$B$11*Assumptions!$C$11+E11*Assumptions!$B$12*Assumptions!$C$12 -> 3744
A15: Deepest fuse cavity (mm) | B15: =MAX(0,IF(B5>0,Assumptions!$D$6,0),IF(B6>0,Assumptions!$D$7,0),IF(B7>0,Assumptions!$D$8,0),IF(B8>0,Assumptions!$D$9,0)) -> 18 | C15: =MAX(0,IF(C5>0,Assumptions!$D$6,0),IF(C6>0,Assumptions!$D$7,0),IF(C7>0,Assumptions!$D$8,0),IF(C8>0,Assumptions!$D$9,0)) -> 18 | D15: =MAX(0,IF(D5>0,Assumptions!$D$6,0),IF(D6>0,Assumptions!$D$7,0),IF(D7>0,Assumptions!$D$8,0),IF(D8>0,Assumptions!$D$9,0)) -> 18 | E15: =MAX(0,IF(E5>0,Assumptions!$D$6,0),IF(E6>0,Assumptions!$D$7,0),IF(E7>0,Assumptions!$D$8,0),IF(E8>0,Assumptions!$D$9,0)) -> 18
A16: Tallest relay (mm) | B16: =MAX(0,IF(B9>0,Assumptions!$D$10,0),IF(B10>0,Assumptions!$D$11,0),IF(B11>0,Assumptions!$D$12,0)) -> 22 | C16: =MAX(0,IF(C9>0,Assumptions!$D$10,0),IF(C10>0,Assumptions!$D$11,0),IF(C11>0,Assumptions!$D$12,0)) -> 22 | D16: =MAX(0,IF(D9>0,Assumptions!$D$10,0),IF(D10>0,Assumptions!$D$11,0),IF(D11>0,Assumptions!$D$12,0)) -> 22 | E16: =MAX(0,IF(E9>0,Assumptions!$D$10,0),IF(E10>0,Assumptions!$D$11,0),IF(E11>0,Assumptions!$D$12,0)) -> 22
A17: Cavity rib volume (mm³) | B17: =B5*(Assumptions!$B$6+Assumptions!$C$6)*Assumptions!$B$20*Assumptions!$D$6+B6*(Assumptions!$B$7+Assumptions!$C$7)*Assumptions!$B$20*Assumptions!$D$7+B7*(Assumptions!$B$8+Assumptions!$C$8)*Assumptions!$B$20*Assumptions!$D$8+B8*(Assumptions!$B$9+Assumptions!$C$9)*Assumptions!$B$20*Assumptions!$D$9 -> 14852.4 | C17: =C5*(Assumptions!$B$6+Assumptions!$C$6)*Assumptions!$B$20*Assumptions!$D$6+C6*(Assumptions!$B$7+Assumptions!$C$7)*Assumptions!$B$20*Assumptions!$D$7+C7*(Assumptions!$B$8+Assumptions!$C$8)*Assumptions!$B$20*Assumptions!$D$8+C8*(Assumptions!$B$9+Assumptions!$C$9)*Assumptions!$B$20*Assumptions!$D$9 -> 15188.4 | D17: =D5*(Assumptions!$B$6+Assumptions!$C$6)*Assumptions!$B$20*Assumptions!$D$6+D6*(Assumptions!$B$7+Assumptions!$C$7)*Assumptions!$B$20*Assumptions!$D$7+D7*(Assumptions!$B$8+Assumptions!$C$8)*Assumptions!$B$20*Assumptions!$D$8+D8*(Assumptions!$B$9+Assumptions!$C$9)*Assumptions!$B$20*Assumptions!$D$9 -> 15275.4 | E17: =E5*(Assumptions!$B$6+Assumptions!$C$6)*Assumptions!$B$20*Assumptions!$D$6+E6*(Assumptions!$B$7+Assumptions!$C$7)*Assumptions!$B$20*Assumptions!$D$7+E7*(Assumptions!$B$8+Assumptions!$C$8)*Assumptions!$B$20*Assumptions!$D$8+E8*(Assumptions!$B$9+Assumptions!$C$9)*Assumptions!$B$20*Assumptions!$D$9 -> 14852.4
A18: Component area per layout (mm²) | B18: =IF(Estimator!$B$16="Under",MAX(B13,B14),B13+B14) -> 7385 | C18: =IF(Estimator!$B$16="Under",MAX(C13,C14),C13+C14) -> 7454 | D18: =IF(Estimator!$B$16="Under",MAX(D13,D14),D13+D14) -> 7495.5 | E18: =IF(Estimator!$B$16="Under",MAX(E13,E14),E13+E14) -> 7609
A19: Usable field area (mm²) | B19: =IF(Assumptions!$B$15>0,B18/Assumptions!$B$15,0)+Assumptions!$B$16 -> 13861.538 | C19: =IF(Assumptions!$B$15>0,C18/Assumptions!$B$15,0)+Assumptions!$B$16 -> 13967.692 | D19: =IF(Assumptions!$B$15>0,D18/Assumptions!$B$15,0)+Assumptions!$B$16 -> 14031.538 | E19: =IF(Assumptions!$B$15>0,E18/Assumptions!$B$15,0)+Assumptions!$B$16 -> 14206.154
A20: Field width (mm) | B20: =IF(Assumptions!$B$18>0,SQRT(B19/Assumptions!$B$18),0) -> 96.130254 | C20: =IF(Assumptions!$B$18>0,SQRT(C19/Assumptions!$B$18),0) -> 96.497642 | D20: =IF(Assumptions!$B$18>0,SQRT(D19/Assumptions!$B$18),0) -> 96.717935 | E20: =IF(Assumptions!$B$18>0,SQRT(E19/Assumptions!$B$18),0) -> 97.317877
A21: Field length (mm) | B21: =B20*Assumptions!$B$18 -> 144.19538 | C21: =C20*Assumptions!$B$18 -> 144.74646 | D21: =D20*Assumptions!$B$18 -> 145.0769 | E21: =E20*Assumptions!$B$18 -> 145.97682
A22: Part geometry
A23: Housing L (mm) | B23: =B21+2*Assumptions!$B$17+2*Assumptions!$B$19 -> 161.19538 | C23: =C21+2*Assumptions!$B$17+2*Assumptions!$B$19 -> 161.74646 | D23: =D21+2*Assumptions!$B$17+2*Assumptions!$B$19 -> 162.0769 | E23: =E21+2*Assumptions!$B$17+2*Assumptions!$B$19 -> 162.97682
A24: Housing W (mm) | B24: =B20+2*Assumptions!$B$17+2*Assumptions!$B$19 -> 113.13025 | C24: =C20+2*Assumptions!$B$17+2*Assumptions!$B$19 -> 113.49764 | D24: =D20+2*Assumptions!$B$17+2*Assumptions!$B$19 -> 113.71794 | E24: =E20+2*Assumptions!$B$17+2*Assumptions!$B$19 -> 114.31788
A25: Housing H (mm) | B25: =B15+Assumptions!$B$21 -> 28 | C25: =C15+Assumptions!$B$21 -> 28 | D25: =D15+Assumptions!$B$21 -> 28 | E25: =E15+Assumptions!$B$21 -> 28
A26: Housing volume (mm³) | B26: =B23*B24*Assumptions!$B$19+2*(B23+B24)*B25*Assumptions!$B$19+B17 -> 98848.174 | C26: =C23*C24*Assumptions!$B$19+2*(C23+C24)*C25*Assumptions!$B$19+C17 -> 99617.18 | D26: =D23*D24*Assumptions!$B$19+2*(D23+D24)*D25*Assumptions!$B$19+D17 -> 99964.304 | E26: =E23*E24*Assumptions!$B$19+2*(E23+E24)*E25*Assumptions!$B$19+E17 -> 100251.57
A27: Cover L (mm) | B27: =B23+2*(Assumptions!$B$22+0.5) -> 166.19538 | C27: =C23+2*(Assumptions!$B$22+0.5) -> 166.74646 | D27: =D23+2*(Assumptions!$B$22+0.5) -> 167.0769 | E27: =E23+2*(Assumptions!$B$22+0.5) -> 167.97682
A28: Cover W (mm) | B28: =B24+2*(Assumptions!$B$22+0.5) -> 118.13025 | C28: =C24+2*(Assumptions!$B$22+0.5) -> 118.49764 | D28: =D24+2*(Assumptions!$B$22+0.5) -> 118.71794 | E28: =E24+2*(Assumptions!$B$22+0.5) -> 119.31788
A29: Upper cover H (mm) | B29: =Assumptions!$B$23+Assumptions!$B$24 -> 14 | C29: =Assumptions!$B$23+Assumptions!$B$24 -> 14 | D29: =Assumptions!$B$23+Assumptions!$B$24 -> 14 | E29: =Assumptions!$B$23+Assumptions!$B$24 -> 14
A30: Lower cover H (mm) | B30: =MAX(Assumptions!$B$25,B16+Assumptions!$B$24) -> 28 | C30: =MAX(Assumptions!$B$25,C16+Assumptions!$B$24) -> 28 | D30: =MAX(Assumptions!$B$25,D16+Assumptions!$B$24) -> 28 | E30: =MAX(Assumptions!$B$25,E16+Assumptions!$B$24) -> 28
A31: Upper cover volume (mm³) | B31: =B27*B28*Assumptions!$B$22+2*(B27+B28)*B29*Assumptions!$B$22 -> 55187.64 | C31: =C27*C28*Assumptions!$B$22+2*(C27+C28)*C29*Assumptions!$B$22 -> 55491.795 | D31: =D27*D28*Assumptions!$B$22+2*(D27+D28)*D29*Assumptions!$B$22 -> 55674.561 | E31: =E27*E28*Assumptions!$B$22+2*(E27+E28)*E29*Assumptions!$B$22 -> 56173.777
A32: Lower cover volume (mm³) | B32: =B27*B28*Assumptions!$B$22+2*(B27+B28)*B30*Assumptions!$B$22 -> 71109.876 | C32: =C27*C28*Assumptions!$B$22+2*(C27+C28)*C30*Assumptions!$B$22 -> 71465.465 | D32: =D27*D28*Assumptions!$B$22+2*(D27+D28)*D30*Assumptions!$B$22 -> 71679.072 | E32: =E27*E28*Assumptions!$B$22+2*(E27+E28)*E30*Assumptions!$B$22 -> 72262.28
A33: Main housing
A34: Mass (g) | B34: =B26/1000*INDEX(Assumptions!$B$29:$B$31,MATCH(Estimator!$B$18,Assumptions!$A$29:$A$31,0)) -> 134.43352 | C34: =C26/1000*INDEX(Assumptions!$B$29:$B$31,MATCH(Estimator!$B$18,Assumptions!$A$29:$A$31,0)) -> 135.47936 | D34: =D26/1000*INDEX(Assumptions!$B$29:$B$31,MATCH(Estimator!$B$18,Assumptions!$A$29:$A$31,0)) -> 135.95145 | E34: =E26/1000*INDEX(Assumptions!$B$29:$B$31,MATCH(Estimator!$B$18,Assumptions!$A$29:$A$31,0)) -> 136.34213
A35: Material ($) | B35: =B34/1000*(1+Assumptions!$B$34)*INDEX(Assumptions!$C$29:$C$31,MATCH(Estimator!$B$18,Assumptions!$A$29:$A$31,0)) -> 0.55171515 | C35: =C34/1000*(1+Assumptions!$B$34)*INDEX(Assumptions!$C$29:$C$31,MATCH(Estimator!$B$18,Assumptions!$A$29:$A$31,0)) -> 0.55600731 | D35: =D34/1000*(1+Assumptions!$B$34)*INDEX(Assumptions!$C$29:$C$31,MATCH(Estimator!$B$18,Assumptions!$A$29:$A$31,0)) -> 0.55794477 | E35: =E34/1000*(1+Assumptions!$B$34)*INDEX(Assumptions!$C$29:$C$31,MATCH(Estimator!$B$18,Assumptions!$A$29:$A$31,0)) -> 0.5595481
A36: Clamp tonnage (t) | B36: =B23*B24/645.16*Assumptions!$B$37*Estimator!$B$17 -> 197.8618 | C36: =C23*C24/645.16*Assumptions!$B$37*Estimator!$B$17 -> 199.18298 | D36: =D23*D24/645.16*Assumptions!$B$37*Estimator!$B$17 -> 199.9773 | E36: =E23*E24/645.16*Assumptions!$B$37*Estimator!$B$17 -> 202.14853
A37: Cycle time (s) | B37: =Assumptions!$B$35+Assumptions!$B$36*Assumptions!$B$19^2 -> 24.5 | C37: =Assumptions!$B$35+Assumptions!$B$36*Assumptions!$B$19^2 -> 24.5 | D37: =Assumptions!$B$35+Assumptions!$B$36*Assumptions!$B$19^2 -> 24.5 | E37: =Assumptions!$B$35+Assumptions!$B$36*Assumptions!$B$19^2 -> 24.5
A38: Press rate ($/hr) | B38: =IF(B36<300,Assumptions!$B$38,IF(B36<500,Assumptions!$B$39,IF(B36<800,Assumptions!$B$40,Assumptions!$B$41))) -> 45 | C38: =IF(C36<300,Assumptions!$B$38,IF(C36<500,Assumptions!$B$39,IF(C36<800,Assumptions!$B$40,Assumptions!$B$41))) -> 45 | D38: =IF(D36<300,Assumptions!$B$38,IF(D36<500,Assumptions!$B$39,IF(D36<800,Assumptions!$B$40,Assumptions!$B$41))) -> 45 | E38: =IF(E36<300,Assumptions!$B$38,IF(E36<500,Assumptions!$B$39,IF(E36<800,Assumptions!$B$40,Assumptions!$B$41))) -> 45
A39: Molding ($) | B39: =B38/3600*B37/Estimator!$B$17 -> 0.153125 | C39: =C38/3600*C37/Estimator!$B$17 -> 0.153125 | D39: =D38/3600*D37/Estimator!$B$17 -> 0.153125 | E39: =E38/3600*E37/Estimator!$B$17 -> 0.153125
A40: Part cost ($) | B40: =B35+B39 -> 0.70484015 | C40: =C35+C39 -> 0.70913231 | D40: =D35+D39 -> 0.71106977 | E40: =E35+E39 -> 0.7126731
...
