Workbook

Sheet Estimator
A1: EDC Plastic Cost Estimator v1.1
A2: Enter fuse and relay counts. Get housing + cover size, weight and per-part cost.
A3: Legend: yellow cells with blue text are inputs; everything else is calculated. Material and molding assumptions live on the Assumptions tab.
A5: Inputs | D5: Results
A6: Fuses | B6: Count | D6: Plastic cost per EDC set | E6: =Calc!B79
A7: Micro2 | B7: 20 | D7: Total plastic (g) | E7: =Calc!B80
A8: Micro3 | B8: 10 | D8: Outer footprint L (mm) | E8: =Calc!B27
A9: M-Case | B9: 6 | D9: Outer footprint W (mm) | E9: =Calc!B28
A10: A1S (placeholder size) | B10: 2 | D10: Stack height (mm) | E10: =Calc!B81
A11: PCB relays | B11: Count
A12: Micro PCB relay (up to 35 A) | B12: 8 | D12: Marginal cost
A13: Mini PCB relay (35-70 A) | B13: 4 | D13: Each extra Micro2 adds | E13: =Calc!C79-Calc!B79
A14: High-current PCB relay (70 A+) | B14: 0 | D14: Each extra Micro3 adds | E14: =Calc!D79-Calc!B79
A15: Options | B15: Value | D15: Each extra Micro PCB relay adds | E15: =Calc!E79-Calc!B79
A16: Relay layout (relative to fuses) | B16: Beside
A17: Cavities per mold | B17: 2
A18: Main housing resin | B18: PA66-GF30
A19: Upper cover resin | B19: PA66-GF30
A20: Lower cover resin | B20: PA66-GF30
A21: Labor rate ($/hr, loaded) | B21: 6
A22: Operators per press | B22: 0.5
A24: Press and machine rate (leave blank to use the rule of thumb)
B25: Main housing | C25: Upper cover | D25: Lower cover
A26: Press used (US t)
A27: Machine rate ($/hr)
A29: Per-part breakdown
B30: Main housing | C30: Upper cover | D30: Lower cover
A31: Resin | B31: =Estimator!$B$18 | C31: =Estimator!$B$19 | D31: =Estimator!$B$20
A32: L (mm) | B32: =Calc!B23 | C32: =Calc!B27 | D32: =Calc!B27
A33: W (mm) | B33: =Calc!B24 | C33: =Calc!B28 | D33: =Calc!B28
A34: H (mm) | B34: =Calc!B25 | C34: =Calc!B29 | D34: =Calc!B30
A35: Volume (cm³) | B35: =Calc!B26/1000 | C35: =Calc!B31/1000 | D35: =Calc!B32/1000
A36: Mass (g) | B36: =Calc!B34 | C36: =Calc!B49 | D36: =Calc!B64
A37: Shot weight incl. runner (g) | B37: =Calc!B37 | C37: =Calc!B52 | D37: =Calc!B67
A38: Material incl. runner | B38: =Calc!B35 | C38: =Calc!B50 | D38: =Calc!B65
A39: Projected area incl. runner (in²) | B39: =Calc!B38 | C39: =Calc!B53 | D39: =Calc!B68
A40: Rule-of-thumb clamp (US t) | B40: =Calc!B39 | C40: =Calc!B54 | D40: =Calc!B69
A41: Rule-of-thumb clamp (metric t) | B41: =Calc!B40 | C41: =Calc!B55 | D41: =Calc!B70
A42: Press used (US t) | B42: =Calc!B41 | C42: =Calc!B56 | D42: =Calc!B71
A43: Machine + labor ($/hr) | B43: =Calc!B44+Calc!B45 | C43: =Calc!B59+Calc!B60 | D43: =Calc!B74+Calc!B75
...

Sheet Assumptions
A1: Assumptions (edit the yellow cells to match your parts)
A2: Values are the defaults from the web estimator. Blue text on yellow = input. A1S footprint is a placeholder until real numbers are available.
A4: Component footprints
A5: Part | B5: L (mm) | C5: W (mm) | D5: H (mm)
A6: Micro2 | B6: 11.5 | C6: 6 | D6: 16
A7: Micro3 | B7: 17 | C7: 6.5 | D7: 15
A8: M-Case | B8: 15 | C8: 10 | D8: 14
A9: A1S (placeholder size) | B9: 20 | C9: 12 | D9: 18
A10: Micro PCB relay (up to 35 A) | B10: 16 | C10: 14 | D10: 15
A11: Mini PCB relay (35-70 A) | B11: 24 | C11: 18 | D11: 22
A12: High-current PCB relay (70 A+) | B12: 32 | C12: 24 | D12: 28
A14: Housing geometry
A15: Packing efficiency (0-1) | B15: 0.65
A16: Connector / stud area (mm²) | B16: 2500
A17: Edge margin (mm) | B17: 6
A18: Aspect ratio L:W | B18: 1.5
A19: Housing wall (mm) | B19: 2.5
A20: Cavity rib (mm) | B20: 1.2
A21: PCB + busbar stack (mm) | B21: 10
A22: Cover wall (mm) | B22: 2
A23: Fuse head above housing (mm) | B23: 8
A24: Cover clearance (mm) | B24: 6
A25: Min lower cover height (mm) | B25: 15
A27: Resins
A28: Resin | B28: Density (g/cm³) | C28: Price ($/kg)
A29: PA66-GF30 | B29: 1.36 | C29: 3.8
A30: PBT-GF30 | B30: 1.53 | C30: 3.2
A31: PP-T20 | B31: 1.05 | C31: 1.8
A33: Molding
A34: Runner volume (% of part volume) | B34: 0.08
A35: Runner projected area (% of part area) | B35: 0.1
A36: Cycle base (s) | B36: 12
A37: Cooling k (s/mm²) | B37: 2
A38: Clamp (US tons/in²) | B38: 3.5
A40: Machine rate bands (machine only, labor is on the Estimator)
A41: Band | B41: Press below (US t) | C41: Machine $/hr
A42: Band 1 | B42: 300 | C42: 45
A43: Band 2 | B43: 500 | C43: 60
A44: Band 3 | B44: 800 | C44: 80
A45: Band 4 | B45: Above | C45: 110
...

Sheet Calc
A1: Calculation engine (no inputs here)
A2: Column B is the estimate. C-E add one part each so the Estimator can show marginal cost.
A3: Line item | B3: Base | C3: +1 Micro2 | D3: +1 Micro3 | E3: +1 Micro PCB relay
A4: Counts
A5: Micro2 count | B5: =Estimator!$B$7+0 | C5: =Estimator!$B$7+1 | D5: =Estimator!$B$7+0 | E5: =Estimator!$B$7+0
A6: Micro3 count | B6: =Estimator!$B$8+0 | C6: =Estimator!$B$8+0 | D6: =Estimator!$B$8+1 | E6: =Estimator!$B$8+0
A7: M-Case count | B7: =Estimator!$B$9+0 | C7: =Estimator!$B$9+0 | D7: =Estimator!$B$9+0 | E7: =Estimator!$B$9+0
A8: A1S (placeholder size) count | B8: =Estimator!$B$10+0 | C8: =Estimator!$B$10+0 | D8: =Estimator!$B$10+0 | E8: =Estimator!$B$10+0
A9: Micro PCB relay (up to 35 A) count | B9: =Estimator!$B$12+0 | C9: =Estimator!$B$12+0 | D9: =Estimator!$B$12+0 | E9: =Estimator!$B$12+1
A10: Mini PCB relay (35-70 A) count | B10: =Estimator!$B$13+0 | C10: =Estimator!$B$13+0 | D10: =Estimator!$B$13+0 | E10: =Estimator!$B$13+0
A11: High-current PCB relay (70 A+) count | B11: =Estimator!$B$14+0 | C11: =Estimator!$B$14+0 | D11: =Estimator!$B$14+0 | E11: =Estimator!$B$14+0
A12: Footprint
A13: Fuse cavity area (mm²) | B13: =B5*Assumptions!$B$6*Assumptions!$C$6+B6*Assumptions!$B$7*Assumptions!$C$7+B7*Assumptions!$B$8*Assumptions!$C$8+B8*Assumptions!$B$9*Assumptions!$C$9 | C13: =C5*Assumptions!$B$6*Assumptions!$C$6+C6*Assumptions!$B$7*Assumptions!$C$7+C7*Assumptions!$B$8*Assumptions!$C$8+C8*Assumptions!$B$9*Assumptions!$C$9 | D13: =D5*Assumptions!$B$6*Assumptions!$C$6+D6*Assumptions!$B$7*Assumptions!$C$7+D7*Assumptions!$B$8*Assumptions!$C$8+D8*Assumptions!$B$9*Assumptions!$C$9 | E13: =E5*Assumptions!$B$6*Assumptions!$C$6+E6*Assumptions!$B$7*Assumptions!$C$7+E7*Assumptions!$B$8*Assumptions!$C$8+E8*Assumptions!$B$9*Assumptions!$C$9
A14: Relay area (mm²) | B14: =B9*Assumptions!$B$10*Assumptions!$C$10+B10*Assumptions!$B$11*Assumptions!$C$11+B11*Assumptions!$B$12*Assumptions!$C$12 | C14: =C9*Assumptions!$B$10*Assumptions!$C$10+C10*Assumptions!$B$11*Assumptions!$C$11+C11*Assumptions!$B$12*Assumptions!$C$12 | D14: =D9*Assumptions!$B$10*Assumptions!$C$10+D10*Assumptions!$B$11*Assumptions!$C$11+D11*Assumptions!$B$12*Assumptions!$C$12 | E14: =E9*Assumptions!$B$10*Assumptions!$C$10+E10*Assumptions!$B$11*Assumptions!$C$11+E11*Assumptions!$B$12*Assumptions!$C$12
A15: Deepest fuse cavity (mm) | B15: =MAX(0,IF(B5>0,Assumptions!$D$6,0),IF(B6>0,Assumptions!$D$7,0),IF(B7>0,Assumptions!$D$8,0),IF(B8>0,Assumptions!$D$9,0)) | C15: =MAX(0,IF(C5>0,Assumptions!$D$6,0),IF(C6>0,Assumptions!$D$7,0),IF(C7>0,Assumptions!$D$8,0),IF(C8>0,Assumptions!$D$9,0)) | D15: =MAX(0,IF(D5>0,Assumptions!$D$6,0),IF(D6>0,Assumptions!$D$7,0),IF(D7>0,Assumptions!$D$8,0),IF(D8>0,Assumptions!$D$9,0)) | E15: =MAX(0,IF(E5>0,Assumptions!$D$6,0),IF(E6>0,Assumptions!$D$7,0),IF(E7>0,Assumptions!$D$8,0),IF(E8>0,Assumptions!$D$9,0))
A16: Tallest relay (mm) | B16: =MAX(0,IF(B9>0,Assumptions!$D$10,0),IF(B10>0,Assumptions!$D$11,0),IF(B11>0,Assumptions!$D$12,0)) | C16: =MAX(0,IF(C9>0,Assumptions!$D$10,0),IF(C10>0,Assumptions!$D$11,0),IF(C11>0,Assumptions!$D$12,0)) | D16: =MAX(0,IF(D9>0,Assumptions!$D$10,0),IF(D10>0,Assumptions!$D$11,0),IF(D11>0,Assumptions!$D$12,0)) | E16: =MAX(0,IF(E9>0,Assumptions!$D$10,0),IF(E10>0,Assumptions!$D$11,0),IF(E11>0,Assumptions!$D$12,0))
A17: Cavity rib volume (mm³) | B17: =B5*(Assumptions!$B$6+Assumptions!$C$6)*Assumptions!$B$20*Assumptions!$D$6+B6*(Assumptions!$B$7+Assumptions!$C$7)*Assumptions!$B$20*Assumptions!$D$7+B7*(Assumptions!$B$8+Assumptions!$C$8)*Assumptions!$B$20*Assumptions!$D$8+B8*(Assumptions!$B$9+Assumptions!$C$9)*Assumptions!$B$20*Assumptions!$D$9 | C17: =C5*(Assumptions!$B$6+Assumptions!$C$6)*Assumptions!$B$20*Assumptions!$D$6+C6*(Assumptions!$B$7+Assumptions!$C$7)*Assumptions!$B$20*Assumptions!$D$7+C7*(Assumptions!$B$8+Assumptions!$C$8)*Assumptions!$B$20*Assumptions!$D$8+C8*(Assumptions!$B$9+Assumptions!$C$9)*Assumptions!$B$20*Assumptions!$D$9 | D17: =D5*(Assumptions!$B$6+Assumptions!$C$6)*Assumptions!$B$20*Assumptions!$D$6+D6*(Assumptions!$B$7+Assumptions!$C$7)*Assumptions!$B$20*Assumptions!$D$7+D7*(Assumptions!$B$8+Assumptions!$C$8)*Assumptions!$B$20*Assumptions!$D$8+D8*(Assumptions!$B$9+Assumptions!$C$9)*Assumptions!$B$20*Assumptions!$D$9 | E17: =E5*(Assumptions!$B$6+Assumptions!$C$6)*Assumptions!$B$20*Assumptions!$D$6+E6*(Assumptions!$B$7+Assumptions!$C$7)*Assumptions!$B$20*Assumptions!$D$7+E7*(Assumptions!$B$8+Assumptions!$C$8)*Assumptions!$B$20*Assumptions!$D$8+E8*(Assumptions!$B$9+Assumptions!$C$9)*Assumptions!$B$20*Assumptions!$D$9
A18: Component area per layout (mm²) | B18: =IF(Estimator!$B$16="Under",MAX(B13,B14),B13+B14) | C18: =IF(Estimator!$B$16="Under",MAX(C13,C14),C13+C14) | D18: =IF(Estimator!$B$16="Under",MAX(D13,D14),D13+D14) | E18: =IF(Estimator!$B$16="Under",MAX(E13,E14),E13+E14)
A19: Usable field area (mm²) | B19: =IF(Assumptions!$B$15>0,B18/Assumptions!$B$15,0)+Assumptions!$B$16 | C19: =IF(Assumptions!$B$15>0,C18/Assumptions!$B$15,0)+Assumptions!$B$16 | D19: =IF(Assumptions!$B$15>0,D18/Assumptions!$B$15,0)+Assumptions!$B$16 | E19: =IF(Assumptions!$B$15>0,E18/Assumptions!$B$15,0)+Assumptions!$B$16
A20: Field width (mm) | B20: =IF(Assumptions!$B$18>0,SQRT(B19/Assumptions!$B$18),0) | C20: =IF(Assumptions!$B$18>0,SQRT(C19/Assumptions!$B$18),0) | D20: =IF(Assumptions!$B$18>0,SQRT(D19/Assumptions!$B$18),0) | E20: =IF(Assumptions!$B$18>0,SQRT(E19/Assumptions!$B$18),0)
A21: Field length (mm) | B21: =B20*Assumptions!$B$18 | C21: =C20*Assumptions!$B$18 | D21: =D20*Assumptions!$B$18 | E21: =E20*Assumptions!$B$18
A22: Part geometry
A23: Housing L (mm) | B23: =B21+2*Assumptions!$B$17+2*Assumptions!$B$19 | C23: =C21+2*Assumptions!$B$17+2*Assumptions!$B$19 | D23: =D21+2*Assumptions!$B$17+2*Assumptions!$B$19 | E23: =E21+2*Assumptions!$B$17+2*Assumptions!$B$19
A24: Housing W (mm) | B24: =B20+2*Assumptions!$B$17+2*Assumptions!$B$19 | C24: =C20+2*Assumptions!$B$17+2*Assumptions!$B$19 | D24: =D20+2*Assumptions!$B$17+2*Assumptions!$B$19 | E24: =E20+2*Assumptions!$B$17+2*Assumptions!$B$19
A25: Housing H (mm) | B25: =B15+Assumptions!$B$21 | C25: =C15+Assumptions!$B$21 | D25: =D15+Assumptions!$B$21 | E25: =E15+Assumptions!$B$21
A26: Housing volume (mm³) | B26: =B23*B24*Assumptions!$B$19+2*(B23+B24)*B25*Assumptions!$B$19+B17 | C26: =C23*C24*Assumptions!$B$19+2*(C23+C24)*C25*Assumptions!$B$19+C17 | D26: =D23*D24*Assumptions!$B$19+2*(D23+D24)*D25*Assumptions!$B$19+D17 | E26: =E23*E24*Assumptions!$B$19+2*(E23+E24)*E25*Assumptions!$B$19+E17
A27: Cover L (mm) | B27: =B23+2*(Assumptions!$B$22+0.5) | C27: =C23+2*(Assumptions!$B$22+0.5) | D27: =D23+2*(Assumptions!$B$22+0.5) | E27: =E23+2*(Assumptions!$B$22+0.5)
A28: Cover W (mm) | B28: =B24+2*(Assumptions!$B$22+0.5) | C28: =C24+2*(Assumptions!$B$22+0.5) | D28: =D24+2*(Assumptions!$B$22+0.5) | E28: =E24+2*(Assumptions!$B$22+0.5)
A29: Upper cover H (mm) | B29: =Assumptions!$B$23+Assumptions!$B$24 | C29: =Assumptions!$B$23+Assumptions!$B$24 | D29: =Assumptions!$B$23+Assumptions!$B$24 | E29: =Assumptions!$B$23+Assumptions!$B$24
A30: Lower cover H (mm) | B30: =MAX(Assumptions!$B$25,B16+Assumptions!$B$24) | C30: =MAX(Assumptions!$B$25,C16+Assumptions!$B$24) | D30: =MAX(Assumptions!$B$25,D16+Assumptions!$B$24) | E30: =MAX(Assumptions!$B$25,E16+Assumptions!$B$24)
A31: Upper cover volume (mm³) | B31: =B27*B28*Assumptions!$B$22+2*(B27+B28)*B29*Assumptions!$B$22 | C31: =C27*C28*Assumptions!$B$22+2*(C27+C28)*C29*Assumptions!$B$22 | D31: =D27*D28*Assumptions!$B$22+2*(D27+D28)*D29*Assumptions!$B$22 | E31: =E27*E28*Assumptions!$B$22+2*(E27+E28)*E29*Assumptions!$B$22
A32: Lower cover volume (mm³) | B32: =B27*B28*Assumptions!$B$22+2*(B27+B28)*B30*Assumptions!$B$22 | C32: =C27*C28*Assumptions!$B$22+2*(C27+C28)*C30*Assumptions!$B$22 | D32: =D27*D28*Assumptions!$B$22+2*(D27+D28)*D30*Assumptions!$B$22 | E32: =E27*E28*Assumptions!$B$22+2*(E27+E28)*E30*Assumptions!$B$22
A33: Main housing
A34: Mass (g) | B34: =B26/1000*INDEX(Assumptions!$B$29:$B$31,MATCH(Estimator!$B$18,Assumptions!$A$29:$A$31,0)) | C34: =C26/1000*INDEX(Assumptions!$B$29:$B$31,MATCH(Estimator!$B$18,Assumptions!$A$29:$A$31,0)) | D34: =D26/1000*INDEX(Assumptions!$B$29:$B$31,MATCH(Estimator!$B$18,Assumptions!$A$29:$A$31,0)) | E34: =E26/1000*INDEX(Assumptions!$B$29:$B$31,MATCH(Estimator!$B$18,Assumptions!$A$29:$A$31,0))
A35: Material incl. runner ($) | B35: =B34/1000*(1+Assumptions!$B$34)*INDEX(Assumptions!$C$29:$C$31,MATCH(Estimator!$B$18,Assumptions!$A$29:$A$31,0)) | C35: =C34/1000*(1+Assumptions!$B$34)*INDEX(Assumptions!$C$29:$C$31,MATCH(Estimator!$B$18,Assumptions!$A$29:$A$31,0)) | D35: =D34/1000*(1+Assumptions!$B$34)*INDEX(Assumptions!$C$29:$C$31,MATCH(Estimator!$B$18,Assumptions!$A$29:$A$31,0)) | E35: =E34/1000*(1+Assumptions!$B$34)*INDEX(Assumptions!$C$29:$C$31,MATCH(Estimator!$B$18,Assumptions!$A$29:$A$31,0))
A36: Shot volume incl. runner (cm³) | B36: =B26/1000*Estimator!$B$17*(1+Assumptions!$B$34) | C36: =C26/1000*Estimator!$B$17*(1+Assumptions!$B$34) | D36: =D26/1000*Estimator!$B$17*(1+Assumptions!$B$34) | E36: =E26/1000*Estimator!$B$17*(1+Assumptions!$B$34)
A37: Shot weight incl. runner (g) | B37: =B34*Estimator!$B$17*(1+Assumptions!$B$34) | C37: =C34*Estimator!$B$17*(1+Assumptions!$B$34) | D37: =D34*Estimator!$B$17*(1+Assumptions!$B$34) | E37: =E34*Estimator!$B$17*(1+Assumptions!$B$34)
A38: Projected area incl. runner (in²) | B38: =B23*B24/645.16*Estimator!$B$17*(1+Assumptions!$B$35) | C38: =C23*C24/645.16*Estimator!$B$17*(1+Assumptions!$B$35) | D38: =D23*D24/645.16*Estimator!$B$17*(1+Assumptions!$B$35) | E38: =E23*E24/645.16*Estimator!$B$17*(1+Assumptions!$B$35)
A39: Rule-of-thumb clamp (US t) | B39: =B38*Assumptions!$B$38 | C39: =C38*Assumptions!$B$38 | D39: =D38*Assumptions!$B$38 | E39: =E38*Assumptions!$B$38
A40: Rule-of-thumb clamp (metric t) | B40: =B39*0.90718474 | C40: =C39*0.90718474 | D40: =D39*0.90718474 | E40: =E39*0.90718474
...
