Workbook

Sheet Estimator
A1: Battery Fuse Block Cost Estimator
A2: Blue text on yellow = input. Placeholder assumptions live on the Assumptions sheet. Dimensions in mm, mass in g, cost in $. Example values are filled in.
A4: INPUTS | D4: RESULT
A5: System voltage | B5: 12 | C5: V | D5: Part cost ($) | E5: =B83 -> 6.7173408
A6: Expected load on B+ input | B6: 300 | C6: A | D6: Base L x W x H (mm) | E6: =TEXT(B38,"0.0")&" x "&TEXT(B36,"0.0")&" x "&TEXT(B40,"0.0") -> 77.5 x 149.0 x 20.4
A7: Copper thickness | B7: 2 | C7: mm (0.8 to 5.0) | D7: Plastic mass (g) | E7: =B85 -> 195.78837
A8: Plastic price (PA66-GF30) | B8: 5.5 | C8: $/kg | D8: Copper mass (g) | E8: =B47 -> 94.416
A9: Copper price | B9: 11 | C9: $/kg | D9: Bus width (mm) | E9: =B28 -> 37.5
A10: B+ stud size | B10: M8 | C10: M8, M6 or M5 | D10: Bus width set by | E10: =B29 -> Current load
A11: B+ studs under the cover | B11: 1 | C11: count | D11: Cover L x W (mm) | E11: =TEXT(E65,"0.0")&" x "&TEXT(E66,"0.0") -> 107.5 x 174.0
A12: B+ connection and cover exit | B12: Eyelet 90 degree | C12: see list
A13: Bolt retention method | B13: Over-molded | C13: list
A14: Busbar to bolt joining method | B14: Bolted both sides | C14: list
A16: FUSES
A17: Fuse type | B17: Qty | C17: Bolt | D17: Hole pitch | E17: Body width | F17: Tab thk | G17: Fuse height | H17: Slot width | I17: Min bus width | J17: Stack height | K17: Used | L17: Wall need | M17: Length past input stud | N17: Boss factor | O17: Hardware $/bolt | P17: Rear need
A18: MEGA (M8) | B18: 2 | C18: =INDEX('Fuse Library'!$B$5:$B$7,MATCH($A18,'Fuse Library'!$A$5:$A$7,0)) -> M8 | D18: =INDEX('Fuse Library'!$D$5:$D$7,MATCH($A18,'Fuse Library'!$A$5:$A$7,0)) -> 32 | E18: =INDEX('Fuse Library'!$E$5:$E$7,MATCH($A18,'Fuse Library'!$A$5:$A$7,0)) -> 27 | F18: =INDEX('Fuse Library'!$F$5:$F$7,MATCH($A18,'Fuse Library'!$A$5:$A$7,0)) -> 3 | G18: =INDEX('Fuse Library'!$G$5:$G$7,MATCH($A18,'Fuse Library'!$A$5:$A$7,0)) -> 11 | H18: =MAX(E18,INDEX(Assumptions!$F$31:$F$33,MATCH(C18,Assumptions!$A$31:$A$33,0)),I18+$B$24)+Assumptions!$B$6 -> 29 | I18: =Assumptions!$B$16*INDEX(Assumptions!$B$31:$B$33,MATCH(C18,Assumptions!$A$31:$A$33,0)) -> 20 | J18: =$B$7+F18+Assumptions!$B$20+INDEX(Assumptions!$H$31:$H$33,MATCH(C18,Assumptions!$A$31:$A$33,0))+INDEX(Assumptions!$G$31:$G$33,MATCH(C18,Assumptions!$A$31:$A$33,0)) -> 15.4 | K18: =IF(B18>0,1,0) -> 1 | L18: =MAX(G18,J18) -> 15.4 | M18: =D18+INDEX(Assumptions!$F$31:$F$33,MATCH(C18,Assumptions!$A$31:$A$33,0))/2+Assumptions!$B$5 -> 46 | N18: =INDEX(Assumptions!$J$31:$J$33,MATCH(C18,Assumptions!$A$31:$A$33,0)) -> 1 | O18: =INDEX(Assumptions!$I$31:$I$33,MATCH(C18,Assumptions!$A$31:$A$33,0)) -> 0.3 | P18: =INDEX(Assumptions!$F$31:$F$33,MATCH(C18,Assumptions!$A$31:$A$33,0))/2+Assumptions!$B$5 -> 14
A19: MIDI (M6) | B19: 1 | C19: =INDEX('Fuse Library'!$B$5:$B$7,MATCH($A19,'Fuse Library'!$A$5:$A$7,0)) -> M6 | D19: =INDEX('Fuse Library'!$D$5:$D$7,MATCH($A19,'Fuse Library'!$A$5:$A$7,0)) -> 28.5 | E19: =INDEX('Fuse Library'!$E$5:$E$7,MATCH($A19,'Fuse Library'!$A$5:$A$7,0)) -> 20 | F19: =INDEX('Fuse Library'!$F$5:$F$7,MATCH($A19,'Fuse Library'!$A$5:$A$7,0)) -> 2 | G19: =INDEX('Fuse Library'!$G$5:$G$7,MATCH($A19,'Fuse Library'!$A$5:$A$7,0)) -> 9 | H19: =MAX(E19,INDEX(Assumptions!$F$31:$F$33,MATCH(C19,Assumptions!$A$31:$A$33,0)),I19+$B$24)+Assumptions!$B$6 -> 22 | I19: =Assumptions!$B$16*INDEX(Assumptions!$B$31:$B$33,MATCH(C19,Assumptions!$A$31:$A$33,0)) -> 15 | J19: =$B$7+F19+Assumptions!$B$20+INDEX(Assumptions!$H$31:$H$33,MATCH(C19,Assumptions!$A$31:$A$33,0))+INDEX(Assumptions!$G$31:$G$33,MATCH(C19,Assumptions!$A$31:$A$33,0)) -> 12.8 | K19: =IF(B19>0,1,0) -> 1 | L19: =MAX(G19,J19) -> 12.8 | M19: =D19+INDEX(Assumptions!$F$31:$F$33,MATCH(C19,Assumptions!$A$31:$A$33,0))/2+Assumptions!$B$5 -> 40.5 | N19: =INDEX(Assumptions!$J$31:$J$33,MATCH(C19,Assumptions!$A$31:$A$33,0)) -> 0.75 | O19: =INDEX(Assumptions!$I$31:$I$33,MATCH(C19,Assumptions!$A$31:$A$33,0)) -> 0.18 | P19: =INDEX(Assumptions!$F$31:$F$33,MATCH(C19,Assumptions!$A$31:$A$33,0))/2+Assumptions!$B$5 -> 12
A20: MIDI (M5) | B20: 2 | C20: =INDEX('Fuse Library'!$B$5:$B$7,MATCH($A20,'Fuse Library'!$A$5:$A$7,0)) -> M5 | D20: =INDEX('Fuse Library'!$D$5:$D$7,MATCH($A20,'Fuse Library'!$A$5:$A$7,0)) -> 28.5 | E20: =INDEX('Fuse Library'!$E$5:$E$7,MATCH($A20,'Fuse Library'!$A$5:$A$7,0)) -> 17.5 | F20: =INDEX('Fuse Library'!$F$5:$F$7,MATCH($A20,'Fuse Library'!$A$5:$A$7,0)) -> 2 | G20: =INDEX('Fuse Library'!$G$5:$G$7,MATCH($A20,'Fuse Library'!$A$5:$A$7,0)) -> 9 | H20: =MAX(E20,INDEX(Assumptions!$F$31:$F$33,MATCH(C20,Assumptions!$A$31:$A$33,0)),I20+$B$24)+Assumptions!$B$6 -> 19.5 | I20: =Assumptions!$B$16*INDEX(Assumptions!$B$31:$B$33,MATCH(C20,Assumptions!$A$31:$A$33,0)) -> 12.5 | J20: =$B$7+F20+Assumptions!$B$20+INDEX(Assumptions!$H$31:$H$33,MATCH(C20,Assumptions!$A$31:$A$33,0))+INDEX(Assumptions!$G$31:$G$33,MATCH(C20,Assumptions!$A$31:$A$33,0)) -> 11.7 | K20: =IF(B20>0,1,0) -> 1 | L20: =MAX(G20,J20) -> 11.7 | M20: =D20+INDEX(Assumptions!$F$31:$F$33,MATCH(C20,Assumptions!$A$31:$A$33,0))/2+Assumptions!$B$5 -> 39.5 | N20: =INDEX(Assumptions!$J$31:$J$33,MATCH(C20,Assumptions!$A$31:$A$33,0)) -> 0.6 | O20: =INDEX(Assumptions!$I$31:$I$33,MATCH(C20,Assumptions!$A$31:$A$33,0)) -> 0.14 | P20: =INDEX(Assumptions!$F$31:$F$33,MATCH(C20,Assumptions!$A$31:$A$33,0))/2+Assumptions!$B$5 -> 11
A21: Total fuse positions | B21: =SUM(B18:B20) -> 5
A23: CLEARANCES AND BUS SIZING
A24: Required clearance | B24: =INDEX(Assumptions!$B$23:$B$26,MATCH($B$5,Assumptions!$A$23:$A$26,1)) -> 1.5 | C24: mm
A25: Required creepage | B25: =INDEX(Assumptions!$C$23:$C$26,MATCH($B$5,Assumptions!$A$23:$A$26,1)) -> 2 | C25: mm
A26: Bus width needed for the current | B26: =B6/(Assumptions!$B$14*B7) -> 37.5 | C26: mm
A27: Bus width needed for the bolts | B27: =MAX(SUMPRODUCT(MAX($K$18:$K$20*$I$18:$I$20)),Assumptions!$B$16*INDEX(Assumptions!$B$31:$B$33,MATCH($B$10,Assumptions!$A$31:$A$33,0))) -> 20 | C27: mm
A28: Bus width used | B28: =MAX(B26,B27) -> 37.5 | C28: mm
A29: Bus width is set by | B29: =IF(B26>=B27,"Current load","Bolt size") -> Current load
A30: Resulting current density | B30: =B6/(B28*B7) -> 4 | C30: A/mm2
A32: BLOCK SIZE
A33: Fuse positions | B33: =B21 -> 5
A34: Fuse slots width | B34: =SUMPRODUCT(B18:B20,H18:H20) -> 119 | C34: mm
A35: B+ stud section width | B35: =B11*(INDEX(Assumptions!$F$31:$F$33,MATCH($B$10,Assumptions!$A$31:$A$33,0))+Assumptions!$B$6) -> 25 | C35: mm
A36: Base width | B36: =B34+B35+2*Assumptions!$B$5 -> 149 | C36: mm
A37: Wall height | B37: =SUMPRODUCT(MAX($K$18:$K$20*$L$18:$L$20)) -> 15.4 | C37: mm
A38: Base length | B38: =MAX(MAX(SUMPRODUCT(MAX($K$18:$K$20*$P$18:$P$20)),(B28-B27/2)+B24+Assumptions!$B$5)+SUMPRODUCT(MAX($K$18:$K$20*$M$18:$M$20)),INDEX(Assumptions!$F$31:$F$33,MATCH($B$10,Assumptions!$A$31:$A$33,0))+2*Assumptions!$B$5) -> 77.5 | C38: mm
A39: Divider height (meets creepage) | B39: =MIN(B37,MAX(Assumptions!$B$7*B37,B25)) -> 9.24 | C39: mm
A40: Overall height with cover | B40: =Assumptions!$B$4+B37+Assumptions!$B$8 -> 20.4 | C40: mm
A41: Divider count | B41: =B33+B11-1 -> 5
A43: COPPER
A44: Bus length (B+ stud to past the last input stud) | B44: =B36-2*Assumptions!$B$5-IF(B20>0,H20,IF(B19>0,H19,H18))/2+IF(B20>0,I20,IF(B19>0,I19,I18))/2 -> 140.5 | C44: mm
A45: Bus mass | B45: =B44*B28*B7*Assumptions!$B$13/1000 -> 94.416 | C45: g
...

Sheet Assumptions
A1: Assumptions (placeholders)
A2: Every yellow cell is a placeholder. Replace with your own values, OEM requirements or supplier quotes. Blue text = input. See the Assumption Diagram sheet for a picture of what each dimension controls.
A3: General geometry, material and process
A4: Base floor thickness | B4: 3 | C4: mm | D4: Placeholder
A5: Outer wall thickness | B5: 2.5 | C5: mm | D5: Placeholder
A6: Divider thickness between fuse slots | B6: 2 | C6: mm | D6: Placeholder
A7: Divider height as fraction of wall height | B7: 0.6 | C7: ratio | D7: Raised automatically to meet the creepage value
A8: Cover thickness | B8: 2 | C8: mm | D8: Placeholder
A9: Cover skirt height | B9: 8 | C9: mm | D9: Placeholder
A10: PA66-GF30 density | B10: 1.36 | C10: g/cm3 | D10: Typical datasheet value, confirm with your grade
A11: Rib, boss and detail allowance on base | B11: 0.1 | C11: % | D11: Placeholder, covers ribs and features not modeled
A12: Scrap and runner allowance | B12: 0.05 | C12: % | D12: Placeholder
A13: Copper density | B13: 8.96 | C13: g/cm3 | D13: Standard value
A14: Copper design current density | B14: 4 | C14: A/mm2 | D14: Placeholder, set from your temperature rise target
A15: Plating cost uplift on copper | B15: 0.05 | C15: % | D15: Placeholder, tin plating
... A20: Cable lug thickness on the fuse terminal | B20: 2 | C20: mm | D20: Placeholder, adds to the tallest bolt stack at the output side
A21: Clearance and creepage by system voltage
A22: Lower bound (V) | B22: Clearance (mm) | C22: Creepage (mm) | D22: Note
A23: 0 | B23: 1.5 | C23: 2 | D23: Row used = highest lower bound at or below the system voltage. Placeholders, set to your OEM spec.
A24: 16.01 | B24: 2.5 | C24: 3.5
A25: 32.01 | B25: 3 | C25: 4
A26: 60.01 | B26: 4 | C26: 6
A29: Bolt sizes and OEM socket clearance
A30: Bolt | B30: Thread dia (mm) | C30: Hole dia (mm) | D30: Socket AF (mm) | E30: Socket OD (mm) | F30: Socket clearance dia (mm) | G30: Nut height (mm) | H30: Washer thk (mm) | I30: Hardware $/bolt | J30: Boss size factor
A31: M8 | B31: 8 | C31: 8.5 | D31: 13 | E31: 21 | F31: =E31+2*$B$17 -> 23 | G31: 6.8 | H31: 1.6 | I31: 0.3 | J31: 1
A32: M6 | B32: 6 | C32: 6.5 | D32: 10 | E32: 17 | F32: =E32+2*$B$17 -> 19 | G32: 5.2 | H32: 1.6 | I32: 0.18 | J32: 0.75
A33: M5 | B33: 5 | C33: 5.5 | D33: 8 | E33: 15 | F33: =E33+2*$B$17 -> 17 | G33: 4.7 | H33: 1 | I33: 0.14 | J33: 0.6
A34: Socket OD and hardware cost are placeholders. Nut heights follow ISO 4032 style 1.
A35: Bolt retention method
A36: Method | B36: Boss plastic at M8 (mm3) | C36: Cost per bolt ($) | D36: Note
A37: Over-molded | B37: 2000 | C37: 0.08 | D37: Bolt loaded into the mold as an insert. All numbers are placeholders.
A38: Snap-in from bottom | B38: 3200 | C38: 0.04 | D38: Bolt pressed into a snap boss from underneath. All numbers are placeholders.
A39: Slide-in | B39: 2600 | C39: 0.03 | D39: Bolt head slides into a captured slot. All numbers are placeholders.
A41: Busbar to bolt joining method
A42: Method | B42: Cost per joint ($) | C42: Note
A43: Bolted both sides | B43: 0.1 | C43: Second nut, washer and torque operation. Placeholder.
A44: Clinch | B44: 0.05 | C44: Clinch press operation. Placeholder.
A45: Laser weld | B45: 0.14 | C45: Weld cycle and fixturing. Placeholder.
A47: Cover footprint (cable escape)
A48: Fit gap between cover and base | B48: 0.5 | C48: mm | D48: Placeholder. Cover overhangs the base by cover thickness plus this gap on every side
...

Sheet Assumption Diagram
A1: Assumption diagram
A2: Static pictures drawn with the example values. They do not update when you change a cell. Cell references in the labels point to the Assumptions, Estimator and Fuse Library sheets.

Sheet Fuse Library
A1: Fuse library
A2: Dimensions are approximate placeholders. Replace with values from the Littelfuse drawings before relying on the size output.
A4: Type | B4: Bolt | C4: Amp range (A) | D4: Hole pitch (mm) | E4: Body width (mm) | F4: Tab thk (mm) | G4: Fuse height (mm) | H4: Part number family | I4: Source note
A5: MEGA (M8) | B5: M8 | C5: 40 to 500 | D5: 32 | E5: 27 | F5: 3 | G5: 11 | H5: MEGA bolt-down fuse, 298 series holder | I5: Littelfuse lists M8 studs and MEGA fuses from 40 A to 500 A. Specific fuse part numbers not confirmed.
A6: MIDI (M6) | B6: M6 | C6: up to 200 | D6: 28.5 | E6: 20 | F6: 2 | G6: 9 | H6: MIDI 498 series, M6 hole version, for example 0498200.MXM6 | I6: Littelfuse lists a 200 A MIDI fuse with M6 holes.
A7: MIDI (M5) | B7: M5 | C7: up to 200 | D7: 28.5 | E7: 17.5 | F7: 2 | G7: 9 | H7: MIDI 498 series, standard M5 holes, for example 0498050.MXT and 0498125.MXT | I7: Littelfuse lists M5 holes at 4.5 Nm torque for these ratings.
A9: A fuse with a different hole size needs a different part number. Add a row here and on the Estimator sheet for any new variant.
