Workbook

Sheet Estimator
A1: Battery Fuse Block Cost Estimator
A2: Blue text on yellow = input. Placeholder assumptions live on the Assumptions sheet. Dimensions in mm, mass in g, cost in $. Example values are filled in.
A3: Revision v1.9: busbar thickness limited to copper mill stock sizes (Assumptions A83:A94). Builds on v1.8.
A4: INPUTS | D4: RESULT
A5: System voltage | B5: 12 | C5: V | D5: Part cost ($) | E5: =B86 -> 7.8369922
A6: Expected load on B+ input | B6: 300 | C6: A | D6: Base L x W x H (mm) | E6: =TEXT(B38,"0.0")&" x "&TEXT(B36,"0.0")&" x "&TEXT(B40,"0.0") -> 74.8 x 196.0 x 45.5
A7: Copper thickness | B7: 2 | C7: mm, mill stock (Assumptions A83:A94) | D7: Plastic mass (g) | E7: =B88 -> 267.45824
A8: Plastic price (PA66-GF30) | B8: 5.5 | C8: $/kg | D8: Copper mass (g) | E8: =B48 -> 94.88934
A9: Copper price | B9: 11 | C9: $/kg | D9: Bus width (mm) | E9: =B28 -> 34.805438
A10: B+ stud size | B10: M8 | C10: M8, M6 or M5 | D10: Bus width set by | E10: =B29 -> Temperature limit
A11: B+ studs under the cover | B11: 1 | C11: count | D11: Cover L x W (mm) | E11: =TEXT(E65,"0.0")&" x "&TEXT(E66,"0.0") -> 104.8 x 221.0
A12: B+ connection and cover exit | B12: Eyelet 90 degree | C12: see list | D12: Keepout zones included | E12: =Layout!B75 -> 1
A13: Bolt retention method | B13: Over-molded | C13: list | D13: Fits battery length? | E13: =Layout!B86 -> No limit
A14: Busbar to bolt joining method | B14: Bolted both sides | C14: list | D14: Fits battery depth? | E14: =Layout!B87 -> No limit
A15: Ambient temperature | B15: 105 | C15: C (underhood 105, interior 85) | D15: Bus temperature at load | E15: =TEXT(B31,"0.0")&" C, limit "&TEXT(Assumptions!B69,"0")&" C"&IF(B31>Assumptions!B69+0.05," OVER","") -> 150.0 C, limit 150 C
A16: FUSES
A17: Fuse type | B17: Qty | C17: Bolt | D17: Hole pitch | E17: Body width | F17: Tab thk | G17: Fuse height | H17: Slot pitch | I17: Min bus width | J17: Stack height | K17: Used | L17: Wall need | M17: Length past input stud | N17: Boss factor | O17: Hardware $/bolt | P17: Rear need
A18: MEGA (M8) | B18: 2 | C18: =INDEX('Fuse Library'!$B$5:$B$7,MATCH($A18,'Fuse Library'!$A$5:$A$7,0)) -> M8 | D18: =INDEX('Fuse Library'!$D$5:$D$7,MATCH($A18,'Fuse Library'!$A$5:$A$7,0)) -> 32 | E18: =INDEX('Fuse Library'!$E$5:$E$7,MATCH($A18,'Fuse Library'!$A$5:$A$7,0)) -> 27 | F18: =INDEX('Fuse Library'!$F$5:$F$7,MATCH($A18,'Fuse Library'!$A$5:$A$7,0)) -> 3 | G18: =INDEX('Fuse Library'!$G$5:$G$7,MATCH($A18,'Fuse Library'!$A$5:$A$7,0)) -> 11 | H18: =Layout!F12 -> 29 | I18: =Assumptions!$B$16*INDEX(Assumptions!$B$31:$B$33,MATCH(C18,Assumptions!$A$31:$A$33,0)) -> 20 | J18: =$B$7+F18+Assumptions!$B$20+INDEX(Assumptions!$H$31:$H$33,MATCH(C18,Assumptions!$A$31:$A$33,0))+INDEX(Assumptions!$G$31:$G$33,MATCH(C18,Assumptions!$A$31:$A$33,0)) -> 15.4 | K18: =IF(B18>0,1,0) -> 1 | L18: =MAX(G18,J18) -> 15.4 | M18: =D18+INDEX(Assumptions!$F$31:$F$33,MATCH(C18,Assumptions!$A$31:$A$33,0))/2+Assumptions!$B$5 -> 46 | N18: =INDEX(Assumptions!$J$31:$J$33,MATCH(C18,Assumptions!$A$31:$A$33,0)) -> 1 | O18: =INDEX(Assumptions!$I$31:$I$33,MATCH(C18,Assumptions!$A$31:$A$33,0)) -> 0.3 | P18: =INDEX(Assumptions!$F$31:$F$33,MATCH(C18,Assumptions!$A$31:$A$33,0))/2+Assumptions!$B$5 -> 14
A19: MIDI (M6) | B19: 1 | C19: =INDEX('Fuse Library'!$B$5:$B$7,MATCH($A19,'Fuse Library'!$A$5:$A$7,0)) -> M6 | D19: =INDEX('Fuse Library'!$D$5:$D$7,MATCH($A19,'Fuse Library'!$A$5:$A$7,0)) -> 28.5 | E19: =INDEX('Fuse Library'!$E$5:$E$7,MATCH($A19,'Fuse Library'!$A$5:$A$7,0)) -> 20 | F19: =INDEX('Fuse Library'!$F$5:$F$7,MATCH($A19,'Fuse Library'!$A$5:$A$7,0)) -> 2 | G19: =INDEX('Fuse Library'!$G$5:$G$7,MATCH($A19,'Fuse Library'!$A$5:$A$7,0)) -> 9 | H19: =Layout!F13 -> 22 | I19: =Assumptions!$B$16*INDEX(Assumptions!$B$31:$B$33,MATCH(C19,Assumptions!$A$31:$A$33,0)) -> 15 | J19: =$B$7+F19+Assumptions!$B$20+INDEX(Assumptions!$H$31:$H$33,MATCH(C19,Assumptions!$A$31:$A$33,0))+INDEX(Assumptions!$G$31:$G$33,MATCH(C19,Assumptions!$A$31:$A$33,0)) -> 12.8 | K19: =IF(B19>0,1,0) -> 1 | L19: =MAX(G19,J19) -> 12.8 | M19: =D19+INDEX(Assumptions!$F$31:$F$33,MATCH(C19,Assumptions!$A$31:$A$33,0))/2+Assumptions!$B$5 -> 40.5 | N19: =INDEX(Assumptions!$J$31:$J$33,MATCH(C19,Assumptions!$A$31:$A$33,0)) -> 0.75 | O19: =INDEX(Assumptions!$I$31:$I$33,MATCH(C19,Assumptions!$A$31:$A$33,0)) -> 0.18 | P19: =INDEX(Assumptions!$F$31:$F$33,MATCH(C19,Assumptions!$A$31:$A$33,0))/2+Assumptions!$B$5 -> 12
A20: MIDI (M5) | B20: 2 | C20: =INDEX('Fuse Library'!$B$5:$B$7,MATCH($A20,'Fuse Library'!$A$5:$A$7,0)) -> M5 | D20: =INDEX('Fuse Library'!$D$5:$D$7,MATCH($A20,'Fuse Library'!$A$5:$A$7,0)) -> 28.5 | E20: =INDEX('Fuse Library'!$E$5:$E$7,MATCH($A20,'Fuse Library'!$A$5:$A$7,0)) -> 17.5 | F20: =INDEX('Fuse Library'!$F$5:$F$7,MATCH($A20,'Fuse Library'!$A$5:$A$7,0)) -> 2 | G20: =INDEX('Fuse Library'!$G$5:$G$7,MATCH($A20,'Fuse Library'!$A$5:$A$7,0)) -> 9 | H20: =Layout!F14 -> 19.5 | I20: =Assumptions!$B$16*INDEX(Assumptions!$B$31:$B$33,MATCH(C20,Assumptions!$A$31:$A$33,0)) -> 12.5 | J20: =$B$7+F20+Assumptions!$B$20+INDEX(Assumptions!$H$31:$H$33,MATCH(C20,Assumptions!$A$31:$A$33,0))+INDEX(Assumptions!$G$31:$G$33,MATCH(C20,Assumptions!$A$31:$A$33,0)) -> 11.7 | K20: =IF(B20>0,1,0) -> 1 | L20: =MAX(G20,J20) -> 11.7 | M20: =D20+INDEX(Assumptions!$F$31:$F$33,MATCH(C20,Assumptions!$A$31:$A$33,0))/2+Assumptions!$B$5 -> 39.5 | N20: =INDEX(Assumptions!$J$31:$J$33,MATCH(C20,Assumptions!$A$31:$A$33,0)) -> 0.6 | O20: =INDEX(Assumptions!$I$31:$I$33,MATCH(C20,Assumptions!$A$31:$A$33,0)) -> 0.14 | P20: =INDEX(Assumptions!$F$31:$F$33,MATCH(C20,Assumptions!$A$31:$A$33,0))/2+Assumptions!$B$5 -> 11
A21: Total fuse positions | B21: =SUM(B18:B20) -> 5
A23: CLEARANCES AND BUS SIZING
A24: Required clearance | B24: =INDEX(Assumptions!$B$23:$B$26,MATCH($B$5,Assumptions!$A$23:$A$26,1)) -> 1.5 | C24: mm
A25: Required creepage | B25: =INDEX(Assumptions!$C$23:$C$26,MATCH($B$5,Assumptions!$A$23:$A$26,1)) -> 2 | C25: mm
A26: Bus width needed for the current (by the sizing method) | B26: =IF(Assumptions!$B$80="Current density",Layout!$B$101,Layout!$B$107) -> 34.805438 | C26: mm
A27: Bus width needed for the bolts | B27: =MAX(SUMPRODUCT(MAX($K$18:$K$20*$I$18:$I$20)),Assumptions!$B$16*INDEX(Assumptions!$B$31:$B$33,MATCH($B$10,Assumptions!$A$31:$A$33,0))) -> 20 | C27: mm
A28: Bus width used | B28: =MAX(B26,B27) -> 34.805438 | C28: mm
A29: Bus width is set by | B29: =IF(B26>=B27,IF(Assumptions!$B$80="Current density","Current load","Temperature limit"),"Bolt size") -> Temperature limit
A30: Resulting current density | B30: =B6/(B28*B7) -> 4.3096714 | C30: A/mm2
A31: Estimated bus temperature at load | B31: =B15+Assumptions!$B$62*(B6/(Assumptions!$B$58*Assumptions!$B$63*Assumptions!$B$73*(B28*B7)^Assumptions!$B$59*(2*(B28+B7))^Assumptions!$B$60))^(1/Assumptions!$B$61) -> 150 | C31: C
A32: BLOCK SIZE
A33: Fuse positions | B33: =B21 -> 5
A34: Long-side fuse slots width | B34: =Layout!B54 -> 119 | C34: mm
A35: B+ stud section width | B35: =B11*(INDEX(Assumptions!$F$31:$F$33,MATCH($B$10,Assumptions!$A$31:$A$33,0))+Assumptions!$B$6) -> 25 | C35: mm
A36: Base width | B36: =MAX(B34+Layout!B90+Layout!B76+IF(Layout!B6="Opposite B+",Layout!B64,0)+2*Assumptions!$B$5,Layout!B77-Assumptions!$B$6+2*Assumptions!$B$5) -> 196 | C36: mm
A37: Wall height | B37: =SUMPRODUCT(MAX($K$18:$K$20*$L$18:$L$20)) -> 15.4 | C37: mm
A38: Base length | B38: =MAX(Layout!B61+SUMPRODUCT(MAX((Layout!G12:G14>0)*$M$18:$M$20)),INDEX(Assumptions!$F$31:$F$33,MATCH($B$10,Assumptions!$A$31:$A$33,0))+2*Assumptions!$B$5+Layout!B60,Layout!B68,Layout!B78) -> 74.805438 | C38: mm
A39: Divider height (meets creepage) | B39: =MIN(B37,MAX(Assumptions!$B$7*B37,B25)) -> 9.24 | C39: mm
A40: Overall height with cover (incl. zone bump-out) | B40: =Assumptions!$B$4+MAX(B37,Layout!B79)+Assumptions!$B$8 -> 45.5 | C40: mm
A41: Divider count | B41: =Layout!B72 -> 6
...

Sheet Layout
A1: Layout
A2: Fuse placement, slot pitch, keepout zones and battery fit. Blue on yellow = input. Long side = the side along the fuse row. Short side = the end opposite B+ or the B+ end.
A4: LAYOUT INPUTS
A5: Walls between fuses | B5: Yes | C5: Yes or No. No = sockets may overlap, pitch needs body + creepage | E5: B+ corner | F5: Left | G5: Mirror image only
A6: Short-side outputs exit at | B6: Opposite B+ | C6: Opposite B+ or B+ end | E6: Short-side bus | F6: One piece L | G6: One piece L is costed on its rectangular blank
A7: Max block length along the row | C7: mm, cover outside. Blank = no limit
A8: Max block depth | C8: mm, cover outside. Blank = no limit
A10: FUSE PLACEMENT AND PITCH
A11: Fuse type | B11: Qty | C11: On short side | D11: Pitch override (mm) | E11: Auto pitch (mm) | F11: Pitch used (mm) | G11: On long side | H11: Pitch check | I11: Short used
A12: =Estimator!A18 -> MEGA (M8) | B12: =Estimator!B18 -> 2 | C12: 0 | E12: =IF($B$5="Yes",MAX(Estimator!E18,INDEX(Assumptions!$F$31:$F$33,MATCH(Estimator!C18,Assumptions!$A$31:$A$33,0)),Estimator!I18+Estimator!$B$24)+Assumptions!$B$6,MAX(Estimator!E18+Estimator!$B$25,Estimator!I18+Estimator!$B$24)) -> 29 | F12: =IF(D12="",E12,D12) -> 29 | G12: =B12-I12 -> 2 | H12: =IF(F12<E12,"Below auto: check socket access and creepage","OK") -> OK | I12: =MIN(B12,C12) -> 0
A13: =Estimator!A19 -> MIDI (M6) | B13: =Estimator!B19 -> 1 | C13: 0 | E13: =IF($B$5="Yes",MAX(Estimator!E19,INDEX(Assumptions!$F$31:$F$33,MATCH(Estimator!C19,Assumptions!$A$31:$A$33,0)),Estimator!I19+Estimator!$B$24)+Assumptions!$B$6,MAX(Estimator!E19+Estimator!$B$25,Estimator!I19+Estimator!$B$24)) -> 22 | F13: =IF(D13="",E13,D13) -> 22 | G13: =B13-I13 -> 1 | H13: =IF(F13<E13,"Below auto: check socket access and creepage","OK") -> OK | I13: =MIN(B13,C13) -> 0
A14: =Estimator!A20 -> MIDI (M5) | B14: =Estimator!B20 -> 2 | C14: 0 | E14: =IF($B$5="Yes",MAX(Estimator!E20,INDEX(Assumptions!$F$31:$F$33,MATCH(Estimator!C20,Assumptions!$A$31:$A$33,0)),Estimator!I20+Estimator!$B$24)+Assumptions!$B$6,MAX(Estimator!E20+Estimator!$B$25,Estimator!I20+Estimator!$B$24)) -> 19.5 | F14: =IF(D14="",E14,D14) -> 19.5 | G14: =B14-I14 -> 2 | H14: =IF(F14<E14,"Below auto: check socket access and creepage","OK") -> OK | I14: =MIN(B14,C14) -> 0
A15: Auto pitch with walls = largest of body width, socket clearance and bus edge width + clearance, plus one divider. Without walls = largest of body width + creepage and bus edge width + clearance.
A17: KEEPOUT ZONE INPUTS (SEALED BOXES)
B18: Zone 1 | C18: Zone 2 | D18: Note
A19: Name | B19: Bolted relay | C19: Spare box | D19: Label only
A20: Include in block | B20: Yes | C20: No | D20: Yes or No
A21: Placement | B21: End of row | C21: Back side | D21: End of row, or Back side (behind the bus)
A22: Length, front to back | B22: 60 | C22: 40 | D22: mm
A23: Width, along the fuse row | B23: 45 | C23: 30 | D23: mm
A24: Height above the floor | B24: 40 | C24: 25 | D24: mm. Cover bumps out if taller than the base wall
A25: Studs | B25: 2 | C25: 0 | D25: 0, 1 or 2. Use 0 when the zone is laser welded to the bus
A26: Stud size | B26: M6 | C26: M6 | D26: M8, M6 or M5
A27: Current from the input bus | B27: 100 | C27: 0 | D27: A. 0 = no bus connection. Already part of the B+ load, not added to it
A28: Branch length override | D28: mm. Blank = auto length below
A30: KEEPOUT ZONE CALCULATION
A31: Included (1 = yes) | B31: =IF(B20="Yes",1,0) -> 1 | C31: =IF(C20="Yes",1,0) -> 0
A32: At the end of the row (1 = yes) | B32: =B31*IF(B21="End of row",1,0) -> 1 | C32: =C31*IF(C21="End of row",1,0) -> 0
A33: On the back side (1 = yes) | B33: =B31-B32 -> 0 | C33: =C31-C32 -> 0
A34: Width added to the row | B34: =B32*(B23+Assumptions!$B$6) -> 47 | C34: =C32*(C23+Assumptions!$B$6) -> 0 | D34: mm, zone width plus one divider
A35: Width needed on the back side | B35: =B33*(B23+Assumptions!$B$6) -> 0 | C35: =C33*(C23+Assumptions!$B$6) -> 0 | D35: mm
A36: Depth added on the back side | B36: =B33*(B22+Assumptions!$B$6) -> 0 | C36: =C33*(C22+Assumptions!$B$6) -> 0 | D36: mm, zone length plus one divider in front of it
A37: Base length needed (end of row) | B37: =B32*(B22+2*Assumptions!$B$5+IF($B$55=1,$B$62-Assumptions!$B$5,0)) -> 65 | C37: =C32*(C22+2*Assumptions!$B$5+IF($B$55=1,$B$62-Assumptions!$B$5,0)) -> 0 | D37: mm. Starts in front of the bus when the bus runs past it to the short side
A38: Cover bump-out height | B38: =B31*MAX(0,B24+Assumptions!$B$48-Estimator!$B$37) -> 25.1 | C38: =C31*MAX(0,C24+Assumptions!$B$48-Estimator!$B$37) -> 0 | D38: mm above the base wall
A39: Cover bump-out volume | B39: =2*(B22+B23)*Assumptions!$B$8*B38 -> 10542 | C39: =2*(C22+C23)*Assumptions!$B$8*C38 -> 0 | D39: mm3, side walls of the bump
A40: Studs counted | B40: =B31*B25 -> 2 | C40: =C31*C25 -> 0
A41: Connected to the bus (1 = yes) | B41: =IF(AND(B31=1,B27>0),1,0) -> 1 | C41: =IF(AND(C31=1,C27>0),1,0) -> 0
A42: Branch width | B42: =B41*MAX(B27/(Assumptions!$B$74*Estimator!$B$7),IF(B40>0,Assumptions!$B$16*INDEX(Assumptions!$B$31:$B$33,MATCH(B26,Assumptions!$A$31:$A$33,0)),0)) -> 15 | C42: =C41*MAX(C27/(Assumptions!$B$74*Estimator!$B$7),IF(C40>0,Assumptions!$B$16*INDEX(Assumptions!$B$31:$B$33,MATCH(C26,Assumptions!$A$31:$A$33,0)),0)) -> 0 | D42: mm. Larger of current need and bolt edge distance
A43: Auto branch length | B43: =B41*IF(B33=1,B22/2+Assumptions!$B$6+Estimator!$B$24,IF($B$55=1,B22/2,$B$56/2-$B$57/2+B34/2)) -> 27 | C43: =C41*IF(C33=1,C22/2+Assumptions!$B$6+Estimator!$B$24,IF($B$55=1,C22/2,$B$56/2-$B$57/2+$B$34+C34/2)) -> 0 | D43: mm. Back side: bus to zone centre. End of row: bus end to zone centre
A44: Branch length used | B44: =B41*IF(B28="",B43,B28) -> 27 | C44: =C41*IF(C28="",C43,C28) -> 0 | D44: mm
...

Sheet Busbar Sizer
A1: Busbar Sizer
A2: Quick copper cost for a known bar, and the cheapest mill stock thickness at a fixed current. Ampacity model: Assumptions rows 57 to 63 and 69 to 73.
A4: INPUTS
A5: Current | B5: 300 | C5: A
A6: Allowed temperature rise (max bus temp - ambient) | B6: =Assumptions!$B$69-Estimator!$B$15 -> 45 | C6: C. Ambient is Estimator B15, max temp is Assumptions B69
A7: Bar length | B7: 150 | C7: mm
A8: Known bar width | B8: 40 | C8: mm
A9: Known bar thickness | B9: 2 | C9: mm, mill stock (Assumptions A83:A94)
A10: Copper price | B10: =Estimator!B9 -> 11 | C10: $/kg, linked to the Estimator
A11: Max width that fits the package | B11: 30 | C11: mm
A12: KNOWN BAR
A13: Width to thickness ratio | B13: =B8/B9 -> 20 | C13: : 1
A14: Cross-section area | B14: =B8*B9 -> 80 | C14: mm2
A15: Perimeter | B15: =2*(B8+B9) -> 84 | C15: mm
A16: Current density | B16: =B5/B14 -> 3.75 | C16: A/mm2
A17: Rated current at the allowed rise | B17: =Assumptions!$B$58*Assumptions!$B$63*Assumptions!$B$73*B14^Assumptions!$B$59*B15^Assumptions!$B$60*(B6/Assumptions!$B$62)^Assumptions!$B$61 -> 338.60179 | C17: A
A18: Estimated temperature rise at the current | B18: =Assumptions!$B$62*(B5/(Assumptions!$B$58*Assumptions!$B$63*Assumptions!$B$73*B14^Assumptions!$B$59*B15^Assumptions!$B$60))^(1/Assumptions!$B$61) -> 36.900775 | C18: C
A19: Carries the current? | B19: =IF(B17>=B5,"Yes","No") -> Yes
A20: Mass | B20: =B7*B14*Assumptions!$B$13/1000 -> 107.52 | C20: g
A21: Copper cost (with plating uplift) | B21: =B20/1000*B10*(1+Assumptions!$B$15) -> 1.241856 | C21: $
A23: STOCK THICKNESS SWEEP AT FIXED CURRENT
A24: Each row is the narrowest bar of that stock thickness that carries the current at the allowed rise. Edit the stock list on Assumptions A83:A94. | K24: Load over k at the allowed rise | L24: Width solve (start, then 6 Newton steps), mm
A25: Stock thickness (mm) | B25: Width needed (mm) | C25: Width : thickness | D25: Area (mm2) | E25: A/mm2 | F25: Mass (g) | G25: Cost ($) | H25: Fits? (width within max) | I25: Cost if it fits ($) | K25: =$B$5/(Assumptions!$B$58*Assumptions!$B$63*Assumptions!$B$73*($B$6/Assumptions!$B$62)^Assumptions!$B$61) -> 44.611408
A26: =IF(Assumptions!$A$83="","",Assumptions!$A$83) -> 0.8 | B26: =IF($A26="","",R26) -> 59.332546 | C26: =IF($A26="","",B26/A26) -> 74.165683 | D26: =IF($A26="","",A26*B26) -> 47.466037 | E26: =IF($A26="","",$B$5/D26) -> 6.3203086 | F26: =IF($A26="","",$B$7*D26*Assumptions!$B$13/1000) -> 63.794354 | G26: =IF($A26="","",F26/1000*$B$10*(1+Assumptions!$B$15)) -> 0.73682478 | H26: =IF($A26="","",IF(B26<=$B$11,"Yes","No")) -> No | I26: =IF(H26="Yes",G26,"") | L26: =IF($A26="","",$B$5/(Assumptions!$B$74*$A26)) -> 93.75 | M26: =IF($A26="","",IF($B$5<=0,0,L26*EXP(-(Assumptions!$B$59*LN(L26*$A26)+Assumptions!$B$60*LN(2*(L26+$A26))-LN($K$25))/(Assumptions!$B$59+Assumptions!$B$60*L26/(L26+$A26))))) -> 59.35931 | N26: =IF($A26="","",IF($B$5<=0,0,M26*EXP(-(Assumptions!$B$59*LN(M26*$A26)+Assumptions!$B$60*LN(2*(M26+$A26))-LN($K$25))/(Assumptions!$B$59+Assumptions!$B$60*M26/(M26+$A26))))) -> 59.332546 | O26: =IF($A26="","",IF($B$5<=0,0,N26*EXP(-(Assumptions!$B$59*LN(N26*$A26)+Assumptions!$B$60*LN(2*(N26+$A26))-LN($K$25))/(Assumptions!$B$59+Assumptions!$B$60*N26/(N26+$A26))))) -> 59.332546 | P26: =IF($A26="","",IF($B$5<=0,0,O26*EXP(-(Assumptions!$B$59*LN(O26*$A26)+Assumptions!$B$60*LN(2*(O26+$A26))-LN($K$25))/(Assumptions!$B$59+Assumptions!$B$60*O26/(O26+$A26))))) -> 59.332546 | Q26: =IF($A26="","",IF($B$5<=0,0,P26*EXP(-(Assumptions!$B$59*LN(P26*$A26)+Assumptions!$B$60*LN(2*(P26+$A26))-LN($K$25))/(Assumptions!$B$59+Assumptions!$B$60*P26/(P26+$A26))))) -> 59.332546 | R26: =IF($A26="","",IF($B$5<=0,0,Q26*EXP(-(Assumptions!$B$59*LN(Q26*$A26)+Assumptions!$B$60*LN(2*(Q26+$A26))-LN($K$25))/(Assumptions!$B$59+Assumptions!$B$60*Q26/(Q26+$A26))))) -> 59.332546
A27: =IF(Assumptions!$A$84="","",Assumptions!$A$84) -> 1 | B27: =IF($A27="","",R27) -> 52.214087 | C27: =IF($A27="","",B27/A27) -> 52.214087 | D27: =IF($A27="","",A27*B27) -> 52.214087 | E27: =IF($A27="","",$B$5/D27) -> 5.7455759 | F27: =IF($A27="","",$B$7*D27*Assumptions!$B$13/1000) -> 70.175734 | G27: =IF($A27="","",F27/1000*$B$10*(1+Assumptions!$B$15)) -> 0.81052972 | H27: =IF($A27="","",IF(B27<=$B$11,"Yes","No")) -> No | I27: =IF(H27="Yes",G27,"") | L27: =IF($A27="","",$B$5/(Assumptions!$B$74*$A27)) -> 75 | M27: =IF($A27="","",IF($B$5<=0,0,L27*EXP(-(Assumptions!$B$59*LN(L27*$A27)+Assumptions!$B$60*LN(2*(L27+$A27))-LN($K$25))/(Assumptions!$B$59+Assumptions!$B$60*L27/(L27+$A27))))) -> 52.2362 | N27: =IF($A27="","",IF($B$5<=0,0,M27*EXP(-(Assumptions!$B$59*LN(M27*$A27)+Assumptions!$B$60*LN(2*(M27+$A27))-LN($K$25))/(Assumptions!$B$59+Assumptions!$B$60*M27/(M27+$A27))))) -> 52.214087 | O27: =IF($A27="","",IF($B$5<=0,0,N27*EXP(-(Assumptions!$B$59*LN(N27*$A27)+Assumptions!$B$60*LN(2*(N27+$A27))-LN($K$25))/(Assumptions!$B$59+Assumptions!$B$60*N27/(N27+$A27))))) -> 52.214087 | P27: =IF($A27="","",IF($B$5<=0,0,O27*EXP(-(Assumptions!$B$59*LN(O27*$A27)+Assumptions!$B$60*LN(2*(O27+$A27))-LN($K$25))/(Assumptions!$B$59+Assumptions!$B$60*O27/(O27+$A27))))) -> 52.214087 | Q27: =IF($A27="","",IF($B$5<=0,0,P27*EXP(-(Assumptions!$B$59*LN(P27*$A27)+Assumptions!$B$60*LN(2*(P27+$A27))-LN($K$25))/(Assumptions!$B$59+Assumptions!$B$60*P27/(P27+$A27))))) -> 52.214087 | R27: =IF($A27="","",IF($B$5<=0,0,Q27*EXP(-(Assumptions!$B$59*LN(Q27*$A27)+Assumptions!$B$60*LN(2*(Q27+$A27))-LN($K$25))/(Assumptions!$B$59+Assumptions!$B$60*Q27/(Q27+$A27))))) -> 52.214087
A28: =IF(Assumptions!$A$85="","",Assumptions!$A$85) -> 1.2 | B28: =IF($A28="","",R28) -> 47.002008 | C28: =IF($A28="","",B28/A28) -> 39.16834 | D28: =IF($A28="","",A28*B28) -> 56.402409 | E28: =IF($A28="","",$B$5/D28) -> 5.3189217 | F28: =IF($A28="","",$B$7*D28*Assumptions!$B$13/1000) -> 75.804838 | G28: =IF($A28="","",F28/1000*$B$10*(1+Assumptions!$B$15)) -> 0.87554588 | H28: =IF($A28="","",IF(B28<=$B$11,"Yes","No")) -> No | I28: =IF(H28="Yes",G28,"") | L28: =IF($A28="","",$B$5/(Assumptions!$B$74*$A28)) -> 62.5 | M28: =IF($A28="","",IF($B$5<=0,0,L28*EXP(-(Assumptions!$B$59*LN(L28*$A28)+Assumptions!$B$60*LN(2*(L28+$A28))-LN($K$25))/(Assumptions!$B$59+Assumptions!$B$60*L28/(L28+$A28))))) -> 47.019121 | N28: =IF($A28="","",IF($B$5<=0,0,M28*EXP(-(Assumptions!$B$59*LN(M28*$A28)+Assumptions!$B$60*LN(2*(M28+$A28))-LN($K$25))/(Assumptions!$B$59+Assumptions!$B$60*M28/(M28+$A28))))) -> 47.002008 | O28: =IF($A28="","",IF($B$5<=0,0,N28*EXP(-(Assumptions!$B$59*LN(N28*$A28)+Assumptions!$B$60*LN(2*(N28+$A28))-LN($K$25))/(Assumptions!$B$59+Assumptions!$B$60*N28/(N28+$A28))))) -> 47.002008 | P28: =IF($A28="","",IF($B$5<=0,0,O28*EXP(-(Assumptions!$B$59*LN(O28*$A28)+Assumptions!$B$60*LN(2*(O28+$A28))-LN($K$25))/(Assumptions!$B$59+Assumptions!$B$60*O28/(O28+$A28))))) -> 47.002008 | Q28: =IF($A28="","",IF($B$5<=0,0,P28*EXP(-(Assumptions!$B$59*LN(P28*$A28)+Assumptions!$B$60*LN(2*(P28+$A28))-LN($K$25))/(Assumptions!$B$59+Assumptions!$B$60*P28/(P28+$A28))))) -> 47.002008 | R28: =IF($A28="","",IF($B$5<=0,0,Q28*EXP(-(Assumptions!$B$59*LN(Q28*$A28)+Assumptions!$B$60*LN(2*(Q28+$A28))-LN($K$25))/(Assumptions!$B$59+Assumptions!$B$60*Q28/(Q28+$A28))))) -> 47.002008
A29: =IF(Assumptions!$A$86="","",Assumptions!$A$86) -> 1.5 | B29: =IF($A29="","",R29) -> 41.274019 | C29: =IF($A29="","",B29/A29) -> 27.516012 | D29: =IF($A29="","",A29*B29) -> 61.911028 | E29: =IF($A29="","",$B$5/D29) -> 4.8456634 | F29: =IF($A29="","",$B$7*D29*Assumptions!$B$13/1000) -> 83.208421 | G29: =IF($A29="","",F29/1000*$B$10*(1+Assumptions!$B$15)) -> 0.96105727 | H29: =IF($A29="","",IF(B29<=$B$11,"Yes","No")) -> No | I29: =IF(H29="Yes",G29,"") | L29: =IF($A29="","",$B$5/(Assumptions!$B$74*$A29)) -> 50 | M29: =IF($A29="","",IF($B$5<=0,0,L29*EXP(-(Assumptions!$B$59*LN(L29*$A29)+Assumptions!$B$60*LN(2*(L29+$A29))-LN($K$25))/(Assumptions!$B$59+Assumptions!$B$60*L29/(L29+$A29))))) -> 41.284146 | N29: =IF($A29="","",IF($B$5<=0,0,M29*EXP(-(Assumptions!$B$59*LN(M29*$A29)+Assumptions!$B$60*LN(2*(M29+$A29))-LN($K$25))/(Assumptions!$B$59+Assumptions!$B$60*M29/(M29+$A29))))) -> 41.274019 | O29: =IF($A29="","",IF($B$5<=0,0,N29*EXP(-(Assumptions!$B$59*LN(N29*$A29)+Assumptions!$B$60*LN(2*(N29+$A29))-LN($K$25))/(Assumptions!$B$59+Assumptions!$B$60*N29/(N29+$A29))))) -> 41.274019 | P29: =IF($A29="","",IF($B$5<=0,0,O29*EXP(-(Assumptions!$B$59*LN(O29*$A29)+Assumptions!$B$60*LN(2*(O29+$A29))-LN($K$25))/(Assumptions!$B$59+Assumptions!$B$60*O29/(O29+$A29))))) -> 41.274019 | Q29: =IF($A29="","",IF($B$5<=0,0,P29*EXP(-(Assumptions!$B$59*LN(P29*$A29)+Assumptions!$B$60*LN(2*(P29+$A29))-LN($K$25))/(Assumptions!$B$59+Assumptions!$B$60*P29/(P29+$A29))))) -> 41.274019 | R29: =IF($A29="","",IF($B$5<=0,0,Q29*EXP(-(Assumptions!$B$59*LN(Q29*$A29)+Assumptions!$B$60*LN(2*(Q29+$A29))-LN($K$25))/(Assumptions!$B$59+Assumptions!$B$60*Q29/(Q29+$A29))))) -> 41.274019
A30: =IF(Assumptions!$A$87="","",Assumptions!$A$87) -> 2 | B30: =IF($A30="","",R30) -> 34.805438 | C30: =IF($A30="","",B30/A30) -> 17.402719 | D30: =IF($A30="","",A30*B30) -> 69.610876 | E30: =IF($A30="","",$B$5/D30) -> 4.3096714 | F30: =IF($A30="","",$B$7*D30*Assumptions!$B$13/1000) -> 93.557018 | G30: =IF($A30="","",F30/1000*$B$10*(1+Assumptions!$B$15)) -> 1.0805836 | H30: =IF($A30="","",IF(B30<=$B$11,"Yes","No")) -> No | I30: =IF(H30="Yes",G30,"") | L30: =IF($A30="","",$B$5/(Assumptions!$B$74*$A30)) -> 37.5 | M30: =IF($A30="","",IF($B$5<=0,0,L30*EXP(-(Assumptions!$B$59*LN(L30*$A30)+Assumptions!$B$60*LN(2*(L30+$A30))-LN($K$25))/(Assumptions!$B$59+Assumptions!$B$60*L30/(L30+$A30))))) -> 34.80757 | N30: =IF($A30="","",IF($B$5<=0,0,M30*EXP(-(Assumptions!$B$59*LN(M30*$A30)+Assumptions!$B$60*LN(2*(M30+$A30))-LN($K$25))/(Assumptions!$B$59+Assumptions!$B$60*M30/(M30+$A30))))) -> 34.805438 | O30: =IF($A30="","",IF($B$5<=0,0,N30*EXP(-(Assumptions!$B$59*LN(N30*$A30)+Assumptions!$B$60*LN(2*(N30+$A30))-LN($K$25))/(Assumptions!$B$59+Assumptions!$B$60*N30/(N30+$A30))))) -> 34.805438 | P30: =IF($A30="","",IF($B$5<=0,0,O30*EXP(-(Assumptions!$B$59*LN(O30*$A30)+Assumptions!$B$60*LN(2*(O30+$A30))-LN($K$25))/(Assumptions!$B$59+Assumptions!$B$60*O30/(O30+$A30))))) -> 34.805438 | Q30: =IF($A30="","",IF($B$5<=0,0,P30*EXP(-(Assumptions!$B$59*LN(P30*$A30)+Assumptions!$B$60*LN(2*(P30+$A30))-LN($K$25))/(Assumptions!$B$59+Assumptions!$B$60*P30/(P30+$A30))))) -> 34.805438 | R30: =IF($A30="","",IF($B$5<=0,0,Q30*EXP(-(Assumptions!$B$59*LN(Q30*$A30)+Assumptions!$B$60*LN(2*(Q30+$A30))-LN($K$25))/(Assumptions!$B$59+Assumptions!$B$60*Q30/(Q30+$A30))))) -> 34.805438
A31: =IF(Assumptions!$A$88="","",Assumptions!$A$88) -> 2.5 | B31: =IF($A31="","",R31) -> 30.394389 | C31: =IF($A31="","",B31/A31) -> 12.157756 | D31: =IF($A31="","",A31*B31) -> 75.985973 | E31: =IF($A31="","",$B$5/D31) -> 3.9480971 | F31: =IF($A31="","",$B$7*D31*Assumptions!$B$13/1000) -> 102.12515 | G31: =IF($A31="","",F31/1000*$B$10*(1+Assumptions!$B$15)) -> 1.1795455 | H31: =IF($A31="","",IF(B31<=$B$11,"Yes","No")) -> No | I31: =IF(H31="Yes",G31,"") | L31: =IF($A31="","",$B$5/(Assumptions!$B$74*$A31)) -> 30 | M31: =IF($A31="","",IF($B$5<=0,0,L31*EXP(-(Assumptions!$B$59*LN(L31*$A31)+Assumptions!$B$60*LN(2*(L31+$A31))-LN($K$25))/(Assumptions!$B$59+Assumptions!$B$60*L31/(L31+$A31))))) -> 30.394472 | N31: =IF($A31="","",IF($B$5<=0,0,M31*EXP(-(Assumptions!$B$59*LN(M31*$A31)+Assumptions!$B$60*LN(2*(M31+$A31))-LN($K$25))/(Assumptions!$B$59+Assumptions!$B$60*M31/(M31+$A31))))) -> 30.394389 | O31: =IF($A31="","",IF($B$5<=0,0,N31*EXP(-(Assumptions!$B$59*LN(N31*$A31)+Assumptions!$B$60*LN(2*(N31+$A31))-LN($K$25))/(Assumptions!$B$59+Assumptions!$B$60*N31/(N31+$A31))))) -> 30.394389 | P31: =IF($A31="","",IF($B$5<=0,0,O31*EXP(-(Assumptions!$B$59*LN(O31*$A31)+Assumptions!$B$60*LN(2*(O31+$A31))-LN($K$25))/(Assumptions!$B$59+Assumptions!$B$60*O31/(O31+$A31))))) -> 30.394389 | Q31: =IF($A31="","",IF($B$5<=0,0,P31*EXP(-(Assumptions!$B$59*LN(P31*$A31)+Assumptions!$B$60*LN(2*(P31+$A31))-LN($K$25))/(Assumptions!$B$59+Assumptions!$B$60*P31/(P31+$A31))))) -> 30.394389 | R31: =IF($A31="","",IF($B$5<=0,0,Q31*EXP(-(Assumptions!$B$59*LN(Q31*$A31)+Assumptions!$B$60*LN(2*(Q31+$A31))-LN($K$25))/(Assumptions!$B$59+Assumptions!$B$60*Q31/(Q31+$A31))))) -> 30.394389
A32: =IF(Assumptions!$A$89="","",Assumptions!$A$89) -> 3 | B32: =IF($A32="","",R32) -> 27.12626 | C32: =IF($A32="","",B32/A32) -> 9.0420868 | D32: =IF($A32="","",A32*B32) -> 81.378781 | E32: =IF($A32="","",$B$5/D32) -> 3.6864647 | F32: =IF($A32="","",$B$7*D32*Assumptions!$B$13/1000) -> 109.37308 | G32: =IF($A32="","",F32/1000*$B$10*(1+Assumptions!$B$15)) -> 1.2632591 | H32: =IF($A32="","",IF(B32<=$B$11,"Yes","No")) -> Yes | I32: =IF(H32="Yes",G32,"") -> 1.2632591 | L32: =IF($A32="","",$B$5/(Assumptions!$B$74*$A32)) -> 25 | M32: =IF($A32="","",IF($B$5<=0,0,L32*EXP(-(Assumptions!$B$59*LN(L32*$A32)+Assumptions!$B$60*LN(2*(L32+$A32))-LN($K$25))/(Assumptions!$B$59+Assumptions!$B$60*L32/(L32+$A32))))) -> 27.130151 | N32: =IF($A32="","",IF($B$5<=0,0,M32*EXP(-(Assumptions!$B$59*LN(M32*$A32)+Assumptions!$B$60*LN(2*(M32+$A32))-LN($K$25))/(Assumptions!$B$59+Assumptions!$B$60*M32/(M32+$A32))))) -> 27.12626 | O32: =IF($A32="","",IF($B$5<=0,0,N32*EXP(-(Assumptions!$B$59*LN(N32*$A32)+Assumptions!$B$60*LN(2*(N32+$A32))-LN($K$25))/(Assumptions!$B$59+Assumptions!$B$60*N32/(N32+$A32))))) -> 27.12626 | P32: =IF($A32="","",IF($B$5<=0,0,O32*EXP(-(Assumptions!$B$59*LN(O32*$A32)+Assumptions!$B$60*LN(2*(O32+$A32))-LN($K$25))/(Assumptions!$B$59+Assumptions!$B$60*O32/(O32+$A32))))) -> 27.12626 | Q32: =IF($A32="","",IF($B$5<=0,0,P32*EXP(-(Assumptions!$B$59*LN(P32*$A32)+Assumptions!$B$60*LN(2*(P32+$A32))-LN($K$25))/(Assumptions!$B$59+Assumptions!$B$60*P32/(P32+$A32))))) -> 27.12626 | R32: =IF($A32="","",IF($B$5<=0,0,Q32*EXP(-(Assumptions!$B$59*LN(Q32*$A32)+Assumptions!$B$60*LN(2*(Q32+$A32))-LN($K$25))/(Assumptions!$B$59+Assumptions!$B$60*Q32/(Q32+$A32))))) -> 27.12626
A33: =IF(Assumptions!$A$90="","",Assumptions!$A$90) -> 4 | B33: =IF($A33="","",R33) -> 22.491093 | C33: =IF($A33="","",B33/A33) -> 5.6227732 | D33: =IF($A33="","",A33*B33) -> 89.964372 | E33: =IF($A33="","",$B$5/D33) -> 3.3346534 | F33: =IF($A33="","",$B$7*D33*Assumptions!$B$13/1000) -> 120.91212 | G33: =IF($A33="","",F33/1000*$B$10*(1+Assumptions!$B$15)) -> 1.3965349 | H33: =IF($A33="","",IF(B33<=$B$11,"Yes","No")) -> Yes | I33: =IF(H33="Yes",G33,"") -> 1.3965349 | L33: =IF($A33="","",$B$5/(Assumptions!$B$74*$A33)) -> 18.75 | M33: =IF($A33="","",IF($B$5<=0,0,L33*EXP(-(Assumptions!$B$59*LN(L33*$A33)+Assumptions!$B$60*LN(2*(L33+$A33))-LN($K$25))/(Assumptions!$B$59+Assumptions!$B$60*L33/(L33+$A33))))) -> 22.515717 | N33: =IF($A33="","",IF($B$5<=0,0,M33*EXP(-(Assumptions!$B$59*LN(M33*$A33)+Assumptions!$B$60*LN(2*(M33+$A33))-LN($K$25))/(Assumptions!$B$59+Assumptions!$B$60*M33/(M33+$A33))))) -> 22.491094 | O33: =IF($A33="","",IF($B$5<=0,0,N33*EXP(-(Assumptions!$B$59*LN(N33*$A33)+Assumptions!$B$60*LN(2*(N33+$A33))-LN($K$25))/(Assumptions!$B$59+Assumptions!$B$60*N33/(N33+$A33))))) -> 22.491093 | P33: =IF($A33="","",IF($B$5<=0,0,O33*EXP(-(Assumptions!$B$59*LN(O33*$A33)+Assumptions!$B$60*LN(2*(O33+$A33))-LN($K$25))/(Assumptions!$B$59+Assumptions!$B$60*O33/(O33+$A33))))) -> 22.491093 | Q33: =IF($A33="","",IF($B$5<=0,0,P33*EXP(-(Assumptions!$B$59*LN(P33*$A33)+Assumptions!$B$60*LN(2*(P33+$A33))-LN($K$25))/(Assumptions!$B$59+Assumptions!$B$60*P33/(P33+$A33))))) -> 22.491093 | R33: =IF($A33="","",IF($B$5<=0,0,Q33*EXP(-(Assumptions!$B$59*LN(Q33*$A33)+Assumptions!$B$60*LN(2*(Q33+$A33))-LN($K$25))/(Assumptions!$B$59+Assumptions!$B$60*Q33/(Q33+$A33))))) -> 22.491093
A34: =IF(Assumptions!$A$91="","",Assumptions!$A$91) -> 5 | B34: =IF($A34="","",R34) -> 19.266775 | C34: =IF($A34="","",B34/A34) -> 3.8533551 | D34: =IF($A34="","",A34*B34) -> 96.333877 | E34: =IF($A34="","",$B$5/D34) -> 3.1141693 | F34: =IF($A34="","",$B$7*D34*Assumptions!$B$13/1000) -> 129.47273 | G34: =IF($A34="","",F34/1000*$B$10*(1+Assumptions!$B$15)) -> 1.49541 | H34: =IF($A34="","",IF(B34<=$B$11,"Yes","No")) -> Yes | I34: =IF(H34="Yes",G34,"") -> 1.49541 | L34: =IF($A34="","",$B$5/(Assumptions!$B$74*$A34)) -> 15 | M34: =IF($A34="","",IF($B$5<=0,0,L34*EXP(-(Assumptions!$B$59*LN(L34*$A34)+Assumptions!$B$60*LN(2*(L34+$A34))-LN($K$25))/(Assumptions!$B$59+Assumptions!$B$60*L34/(L34+$A34))))) -> 19.320201 | N34: =IF($A34="","",IF($B$5<=0,0,M34*EXP(-(Assumptions!$B$59*LN(M34*$A34)+Assumptions!$B$60*LN(2*(M34+$A34))-LN($K$25))/(Assumptions!$B$59+Assumptions!$B$60*M34/(M34+$A34))))) -> 19.266781 | O34: =IF($A34="","",IF($B$5<=0,0,N34*EXP(-(Assumptions!$B$59*LN(N34*$A34)+Assumptions!$B$60*LN(2*(N34+$A34))-LN($K$25))/(Assumptions!$B$59+Assumptions!$B$60*N34/(N34+$A34))))) -> 19.266775 | P34: =IF($A34="","",IF($B$5<=0,0,O34*EXP(-(Assumptions!$B$59*LN(O34*$A34)+Assumptions!$B$60*LN(2*(O34+$A34))-LN($K$25))/(Assumptions!$B$59+Assumptions!$B$60*O34/(O34+$A34))))) -> 19.266775 | Q34: =IF($A34="","",IF($B$5<=0,0,P34*EXP(-(Assumptions!$B$59*LN(P34*$A34)+Assumptions!$B$60*LN(2*(P34+$A34))-LN($K$25))/(Assumptions!$B$59+Assumptions!$B$60*P34/(P34+$A34))))) -> 19.266775 | R34: =IF($A34="","",IF($B$5<=0,0,Q34*EXP(-(Assumptions!$B$59*LN(Q34*$A34)+Assumptions!$B$60*LN(2*(Q34+$A34))-LN($K$25))/(Assumptions!$B$59+Assumptions!$B$60*Q34/(Q34+$A34))))) -> 19.266775
A35: =IF(Assumptions!$A$92="","",Assumptions!$A$92) | B35: =IF($A35="","",R35) | C35: =IF($A35="","",B35/A35) | D35: =IF($A35="","",A35*B35) | E35: =IF($A35="","",$B$5/D35) | F35: =IF($A35="","",$B$7*D35*Assumptions!$B$13/1000) | G35: =IF($A35="","",F35/1000*$B$10*(1+Assumptions!$B$15)) | H35: =IF($A35="","",IF(B35<=$B$11,"Yes","No")) | I35: =IF(H35="Yes",G35,"") | L35: =IF($A35="","",$B$5/(Assumptions!$B$74*$A35)) | M35: =IF($A35="","",IF($B$5<=0,0,L35*EXP(-(Assumptions!$B$59*LN(L35*$A35)+Assumptions!$B$60*LN(2*(L35+$A35))-LN($K$25))/(Assumptions!$B$59+Assumptions!$B$60*L35/(L35+$A35))))) | N35: =IF($A35="","",IF($B$5<=0,0,M35*EXP(-(Assumptions!$B$59*LN(M35*$A35)+Assumptions!$B$60*LN(2*(M35+$A35))-LN($K$25))/(Assumptions!$B$59+Assumptions!$B$60*M35/(M35+$A35))))) | O35: =IF($A35="","",IF($B$5<=0,0,N35*EXP(-(Assumptions!$B$59*LN(N35*$A35)+Assumptions!$B$60*LN(2*(N35+$A35))-LN($K$25))/(Assumptions!$B$59+Assumptions!$B$60*N35/(N35+$A35))))) | P35: =IF($A35="","",IF($B$5<=0,0,O35*EXP(-(Assumptions!$B$59*LN(O35*$A35)+Assumptions!$B$60*LN(2*(O35+$A35))-LN($K$25))/(Assumptions!$B$59+Assumptions!$B$60*O35/(O35+$A35))))) | Q35: =IF($A35="","",IF($B$5<=0,0,P35*EXP(-(Assumptions!$B$59*LN(P35*$A35)+Assumptions!$B$60*LN(2*(P35+$A35))-LN($K$25))/(Assumptions!$B$59+Assumptions!$B$60*P35/(P35+$A35))))) | R35: =IF($A35="","",IF($B$5<=0,0,Q35*EXP(-(Assumptions!$B$59*LN(Q35*$A35)+Assumptions!$B$60*LN(2*(Q35+$A35))-LN($K$25))/(Assumptions!$B$59+Assumptions!$B$60*Q35/(Q35+$A35)))))
A36: =IF(Assumptions!$A$93="","",Assumptions!$A$93) | B36: =IF($A36="","",R36) | C36: =IF($A36="","",B36/A36) | D36: =IF($A36="","",A36*B36) | E36: =IF($A36="","",$B$5/D36) | F36: =IF($A36="","",$B$7*D36*Assumptions!$B$13/1000) | G36: =IF($A36="","",F36/1000*$B$10*(1+Assumptions!$B$15)) | H36: =IF($A36="","",IF(B36<=$B$11,"Yes","No")) | I36: =IF(H36="Yes",G36,"") | L36: =IF($A36="","",$B$5/(Assumptions!$B$74*$A36)) | M36: =IF($A36="","",IF($B$5<=0,0,L36*EXP(-(Assumptions!$B$59*LN(L36*$A36)+Assumptions!$B$60*LN(2*(L36+$A36))-LN($K$25))/(Assumptions!$B$59+Assumptions!$B$60*L36/(L36+$A36))))) | N36: =IF($A36="","",IF($B$5<=0,0,M36*EXP(-(Assumptions!$B$59*LN(M36*$A36)+Assumptions!$B$60*LN(2*(M36+$A36))-LN($K$25))/(Assumptions!$B$59+Assumptions!$B$60*M36/(M36+$A36))))) | O36: =IF($A36="","",IF($B$5<=0,0,N36*EXP(-(Assumptions!$B$59*LN(N36*$A36)+Assumptions!$B$60*LN(2*(N36+$A36))-LN($K$25))/(Assumptions!$B$59+Assumptions!$B$60*N36/(N36+$A36))))) | P36: =IF($A36="","",IF($B$5<=0,0,O36*EXP(-(Assumptions!$B$59*LN(O36*$A36)+Assumptions!$B$60*LN(2*(O36+$A36))-LN($K$25))/(Assumptions!$B$59+Assumptions!$B$60*O36/(O36+$A36))))) | Q36: =IF($A36="","",IF($B$5<=0,0,P36*EXP(-(Assumptions!$B$59*LN(P36*$A36)+Assumptions!$B$60*LN(2*(P36+$A36))-LN($K$25))/(Assumptions!$B$59+Assumptions!$B$60*P36/(P36+$A36))))) | R36: =IF($A36="","",IF($B$5<=0,0,Q36*EXP(-(Assumptions!$B$59*LN(Q36*$A36)+Assumptions!$B$60*LN(2*(Q36+$A36))-LN($K$25))/(Assumptions!$B$59+Assumptions!$B$60*Q36/(Q36+$A36)))))
A37: =IF(Assumptions!$A$94="","",Assumptions!$A$94) | B37: =IF($A37="","",R37) | C37: =IF($A37="","",B37/A37) | D37: =IF($A37="","",A37*B37) | E37: =IF($A37="","",$B$5/D37) | F37: =IF($A37="","",$B$7*D37*Assumptions!$B$13/1000) | G37: =IF($A37="","",F37/1000*$B$10*(1+Assumptions!$B$15)) | H37: =IF($A37="","",IF(B37<=$B$11,"Yes","No")) | I37: =IF(H37="Yes",G37,"") | L37: =IF($A37="","",$B$5/(Assumptions!$B$74*$A37)) | M37: =IF($A37="","",IF($B$5<=0,0,L37*EXP(-(Assumptions!$B$59*LN(L37*$A37)+Assumptions!$B$60*LN(2*(L37+$A37))-LN($K$25))/(Assumptions!$B$59+Assumptions!$B$60*L37/(L37+$A37))))) | N37: =IF($A37="","",IF($B$5<=0,0,M37*EXP(-(Assumptions!$B$59*LN(M37*$A37)+Assumptions!$B$60*LN(2*(M37+$A37))-LN($K$25))/(Assumptions!$B$59+Assumptions!$B$60*M37/(M37+$A37))))) | O37: =IF($A37="","",IF($B$5<=0,0,N37*EXP(-(Assumptions!$B$59*LN(N37*$A37)+Assumptions!$B$60*LN(2*(N37+$A37))-LN($K$25))/(Assumptions!$B$59+Assumptions!$B$60*N37/(N37+$A37))))) | P37: =IF($A37="","",IF($B$5<=0,0,O37*EXP(-(Assumptions!$B$59*LN(O37*$A37)+Assumptions!$B$60*LN(2*(O37+$A37))-LN($K$25))/(Assumptions!$B$59+Assumptions!$B$60*O37/(O37+$A37))))) | Q37: =IF($A37="","",IF($B$5<=0,0,P37*EXP(-(Assumptions!$B$59*LN(P37*$A37)+Assumptions!$B$60*LN(2*(P37+$A37))-LN($K$25))/(Assumptions!$B$59+Assumptions!$B$60*P37/(P37+$A37))))) | R37: =IF($A37="","",IF($B$5<=0,0,Q37*EXP(-(Assumptions!$B$59*LN(Q37*$A37)+Assumptions!$B$60*LN(2*(Q37+$A37))-LN($K$25))/(Assumptions!$B$59+Assumptions!$B$60*Q37/(Q37+$A37)))))
A39: Cheapest stock thickness that fits | B39: =IF(COUNT(I26:I37)=0,"None fit",INDEX(A26:A37,MATCH(MIN(I26:I37),I26:I37,0))) -> 3 | C39: mm
A40: Its cost | B40: =IF(COUNT(I26:I37)=0,"-",MIN(I26:I37)) -> 1.2632591
A41: Its width | B41: =IF(COUNT(I26:I37)=0,"-",INDEX(B26:B37,MATCH(MIN(I26:I37),I26:I37,0))) -> 27.12626 | C41: mm
A42: Cost keeps falling as the bar gets thinner and wider, so the cheapest bar is usually the thinnest stock that fits the max width. Stiffness is the other limit.

Sheet Assumptions
A1: Assumptions (placeholders)
A2: Every yellow cell is a placeholder. Replace with your own values, OEM requirements or supplier quotes. Blue text = input. See the Assumption Diagram sheet for a picture of what each dimension controls.
A3: General geometry, material and process
A4: Base floor thickness | B4: 3 | C4: mm | D4: Placeholder
A5: Outer wall thickness | B5: 2.5 | C5: mm | D5: Placeholder
A6: Divider thickness between fuse slots | B6: 2 | C6: mm | D6: Placeholder
A7: Divider height as fraction of wall height | B7: 0.6 | C7: ratio | D7: Raised automatically to meet the creepage value
A8: Cover thickness | B8: 2 | C8: mm | D8: Placeholder
A9: Cover skirt height | B9: 8 | C9: mm | D9: Placeholder
A10: PA66-GF30 density | B10: 1.36 | C10: g/cm3 | D10: Typical datasheet value, confirm with your grade
A11: Rib, boss and detail allowance on base | B11: 0.1 | C11: % | D11: Placeholder, covers ribs and features not modeled
A12: Scrap and runner allowance | B12: 0.05 | C12: % | D12: Placeholder
A13: Copper density | B13: 8.96 | C13: g/cm3 | D13: Standard value
A14: Copper design current density (100% IACS) | B14: 4 | C14: A/mm2 | D14: Placeholder, set from your temperature rise target
A15: Plating cost uplift on copper | B15: 0.05 | C15: % | D15: Placeholder, tin plating
... A20: Cable lug thickness on the fuse terminal | B20: 2 | C20: mm | D20: Placeholder, adds to the tallest bolt stack at the output side
A21: Clearance and creepage by system voltage
A22: Lower bound (V) | B22: Clearance (mm) | C22: Creepage (mm) | D22: Note
A23: 0 | B23: 1.5 | C23: 2 | D23: Row used = highest lower bound at or below the system voltage. Placeholders, set to your OEM spec.
A24: 16.01 | B24: 2.5 | C24: 3.5
A25: 32.01 | B25: 3 | C25: 4
A26: 60.01 | B26: 4 | C26: 6
A29: Bolt sizes and OEM socket clearance
A30: Bolt | B30: Thread dia (mm) | C30: Hole dia (mm) | D30: Socket AF (mm) | E30: Socket OD (mm) | F30: OEM socket clearance dia (mm) | G30: Nut height (mm) | H30: Washer thk (mm) | I30: Hardware $/bolt | J30: Boss size factor
A31: M8 | B31: 8 | C31: 8.5 | D31: 13 | E31: 21 | F31: 23 | G31: 6.8 | H31: 1.6 | I31: 0.3 | J31: 1
A32: M6 | B32: 6 | C32: 6.5 | D32: 10 | E32: 17 | F32: 19 | G32: 5.2 | H32: 1.6 | I32: 0.18 | J32: 0.75
A33: M5 | B33: 5 | C33: 5.5 | D33: 8 | E33: 15 | F33: 17 | G33: 4.7 | H33: 1 | I33: 0.14 | J33: 0.6
A34: Socket clearance dia (F) is the OEM value: socket + plastic protector + clearance to the protector. Socket OD (E) and B17 are for reference only. Hardware cost is a placeholder.
A35: Bolt retention method
A36: Method | B36: Boss plastic at M8 (mm3) | C36: Cost per bolt ($) | D36: Note
A37: Over-molded | B37: 2000 | C37: 0.08 | D37: Bolt loaded into the mold as an insert. All numbers are placeholders.
A38: Snap-in from bottom | B38: 3200 | C38: 0.04 | D38: Bolt pressed into a snap boss from underneath. All numbers are placeholders.
A39: Slide-in | B39: 2600 | C39: 0.03 | D39: Bolt head slides into a captured slot. All numbers are placeholders.
A41: Busbar to bolt joining method
A42: Method | B42: Cost per joint ($) | C42: Note
A43: Bolted both sides | B43: 0.1 | C43: Second nut, washer and torque operation. Placeholder.
A44: Clinch | B44: 0.05 | C44: Clinch press operation. Placeholder.
A45: Laser weld | B45: 0.14 | C45: Weld cycle and fixturing. Placeholder.
A47: Cover footprint (cable escape)
A48: Fit gap between cover and base | B48: 0.5 | C48: mm | D48: Placeholder. Cover overhangs the base by cover thickness plus this gap on every side
...

Sheet Assumption Diagram
A1: Assumption diagram
A2: Static pictures drawn with the example values. They do not update when you change a cell. Cell references in the labels point to the Assumptions, Estimator and Fuse Library sheets.

Sheet Fuse Library
A1: Fuse library
A2: Dimensions are approximate placeholders. Replace with values from the Littelfuse drawings before relying on the size output.
A4: Type | B4: Bolt | C4: Amp range (A) | D4: Hole pitch (mm) | E4: Body width (mm) | F4: Tab thk (mm) | G4: Fuse height (mm) | H4: Part number family | I4: Source note
A5: MEGA (M8) | B5: M8 | C5: 40 to 500 | D5: 32 | E5: 27 | F5: 3 | G5: 11 | H5: MEGA bolt-down fuse, 298 series holder | I5: Littelfuse lists M8 studs and MEGA fuses from 40 A to 500 A. Specific fuse part numbers not confirmed.
A6: MIDI (M6) | B6: M6 | C6: up to 200 | D6: 28.5 | E6: 20 | F6: 2 | G6: 9 | H6: MIDI 498 series, M6 hole version, for example 0498200.MXM6 | I6: Littelfuse lists a 200 A MIDI fuse with M6 holes.
A7: MIDI (M5) | B7: M5 | C7: up to 200 | D7: 28.5 | E7: 17.5 | F7: 2 | G7: 9 | H7: MIDI 498 series, standard M5 holes, for example 0498050.MXT and 0498125.MXT | I7: Littelfuse lists M5 holes at 4.5 Nm torque for these ratings.
A9: A fuse with a different hole size needs a different part number. Add a row here and on the Estimator sheet for any new variant.
